[2022-12-28 18:28:25,199] {taskinstance.py:1159} INFO - Dependencies all met for <TaskInstance: dados_climaticos.extrai_dados scheduled__2022-09-05T00:00:00+00:00 [queued]>
[2022-12-28 18:28:25,228] {taskinstance.py:1159} INFO - Dependencies all met for <TaskInstance: dados_climaticos.extrai_dados scheduled__2022-09-05T00:00:00+00:00 [queued]>
[2022-12-28 18:28:25,228] {taskinstance.py:1356} INFO - 
--------------------------------------------------------------------------------
[2022-12-28 18:28:25,228] {taskinstance.py:1357} INFO - Starting attempt 1 of 1
[2022-12-28 18:28:25,228] {taskinstance.py:1358} INFO - 
--------------------------------------------------------------------------------
[2022-12-28 18:28:25,290] {taskinstance.py:1377} INFO - Executing <Task(PythonOperator): extrai_dados> on 2022-09-05 00:00:00+00:00
[2022-12-28 18:28:25,296] {standard_task_runner.py:52} INFO - Started process 18416 to run task
[2022-12-28 18:28:25,318] {standard_task_runner.py:79} INFO - Running: ['airflow', 'tasks', 'run', 'dados_climaticos', 'extrai_dados', 'scheduled__2022-09-05T00:00:00+00:00', '--job-id', '17', '--raw', '--subdir', 'DAGS_FOLDER/dados_climaticos.py', '--cfg-path', '/tmp/tmpvbdph316', '--error-file', '/tmp/tmp103mpsen']
[2022-12-28 18:28:25,319] {standard_task_runner.py:80} INFO - Job 17: Subtask extrai_dados
[2022-12-28 18:28:25,460] {task_command.py:370} INFO - Running <TaskInstance: dados_climaticos.extrai_dados scheduled__2022-09-05T00:00:00+00:00 [running]> on host alxavier-airflow
[2022-12-28 18:28:25,545] {taskinstance.py:1889} ERROR - Task failed with exception
Traceback (most recent call last):
  File "/home/alxavier/Documents/airflowalura/venv/lib/python3.9/site-packages/airflow/models/taskinstance.py", line 1451, in _run_raw_task
    self._execute_task_with_callbacks(context, test_mode)
  File "/home/alxavier/Documents/airflowalura/venv/lib/python3.9/site-packages/airflow/models/taskinstance.py", line 1555, in _execute_task_with_callbacks
    task_orig = self.render_templates(context=context)
  File "/home/alxavier/Documents/airflowalura/venv/lib/python3.9/site-packages/airflow/models/taskinstance.py", line 2212, in render_templates
    rendered_task = self.task.render_template_fields(context)
  File "/home/alxavier/Documents/airflowalura/venv/lib/python3.9/site-packages/airflow/models/baseoperator.py", line 1185, in render_template_fields
    self._do_render_template_fields(self, self.template_fields, context, jinja_env, set())
  File "/home/alxavier/Documents/airflowalura/venv/lib/python3.9/site-packages/airflow/utils/session.py", line 71, in wrapper
    return func(*args, session=session, **kwargs)
  File "/home/alxavier/Documents/airflowalura/venv/lib/python3.9/site-packages/airflow/models/abstractoperator.py", line 344, in _do_render_template_fields
    rendered_content = self.render_template(
  File "/home/alxavier/Documents/airflowalura/venv/lib/python3.9/site-packages/airflow/models/abstractoperator.py", line 404, in render_template
    return {key: self.render_template(value, context, jinja_env) for key, value in value.items()}
  File "/home/alxavier/Documents/airflowalura/venv/lib/python3.9/site-packages/airflow/models/abstractoperator.py", line 404, in <dictcomp>
    return {key: self.render_template(value, context, jinja_env) for key, value in value.items()}
  File "/home/alxavier/Documents/airflowalura/venv/lib/python3.9/site-packages/airflow/models/abstractoperator.py", line 387, in render_template
    template = jinja_env.from_string(value)
  File "/home/alxavier/Documents/airflowalura/venv/lib/python3.9/site-packages/jinja2/environment.py", line 1092, in from_string
    return cls.from_code(self, self.compile(source), gs, None)
  File "/home/alxavier/Documents/airflowalura/venv/lib/python3.9/site-packages/jinja2/environment.py", line 757, in compile
    self.handle_exception(source=source_hint)
  File "/home/alxavier/Documents/airflowalura/venv/lib/python3.9/site-packages/jinja2/environment.py", line 925, in handle_exception
    raise rewrite_traceback_stack(source=source)
  File "<unknown>", line 1, in template
jinja2.exceptions.TemplateSyntaxError: unexpected char '"' at 29
[2022-12-28 18:28:25,558] {taskinstance.py:1395} INFO - Marking task as FAILED. dag_id=dados_climaticos, task_id=extrai_dados, execution_date=20220905T000000, start_date=20221228T212825, end_date=20221228T212825
[2022-12-28 18:28:25,599] {standard_task_runner.py:92} ERROR - Failed to execute job 17 for task extrai_dados (unexpected char '"' at 29; 18416)
[2022-12-28 18:28:25,654] {local_task_job.py:156} INFO - Task exited with return code 1
[2022-12-28 18:28:25,709] {local_task_job.py:273} INFO - 0 downstream tasks scheduled from follow-on schedule check
[2022-12-28 18:37:54,209] {taskinstance.py:1159} INFO - Dependencies all met for <TaskInstance: dados_climaticos.extrai_dados scheduled__2022-09-05T00:00:00+00:00 [queued]>
[2022-12-28 18:37:54,249] {taskinstance.py:1159} INFO - Dependencies all met for <TaskInstance: dados_climaticos.extrai_dados scheduled__2022-09-05T00:00:00+00:00 [queued]>
[2022-12-28 18:37:54,252] {taskinstance.py:1356} INFO - 
--------------------------------------------------------------------------------
[2022-12-28 18:37:54,253] {taskinstance.py:1357} INFO - Starting attempt 1 of 1
[2022-12-28 18:37:54,253] {taskinstance.py:1358} INFO - 
--------------------------------------------------------------------------------
[2022-12-28 18:37:54,326] {taskinstance.py:1377} INFO - Executing <Task(PythonOperator): extrai_dados> on 2022-09-05 00:00:00+00:00
[2022-12-28 18:37:54,334] {standard_task_runner.py:52} INFO - Started process 19442 to run task
[2022-12-28 18:37:54,374] {standard_task_runner.py:79} INFO - Running: ['airflow', 'tasks', 'run', 'dados_climaticos', 'extrai_dados', 'scheduled__2022-09-05T00:00:00+00:00', '--job-id', '16', '--raw', '--subdir', 'DAGS_FOLDER/dados_climaticos.py', '--cfg-path', '/tmp/tmprhkkvrov', '--error-file', '/tmp/tmpzb36gxo6']
[2022-12-28 18:37:54,375] {standard_task_runner.py:80} INFO - Job 16: Subtask extrai_dados
[2022-12-28 18:37:54,546] {task_command.py:370} INFO - Running <TaskInstance: dados_climaticos.extrai_dados scheduled__2022-09-05T00:00:00+00:00 [running]> on host alxavier-airflow
[2022-12-28 18:37:54,650] {taskinstance.py:1569} INFO - Exporting the following env vars:
AIRFLOW_CTX_DAG_OWNER=airflow
AIRFLOW_CTX_DAG_ID=dados_climaticos
AIRFLOW_CTX_TASK_ID=extrai_dados
AIRFLOW_CTX_EXECUTION_DATE=2022-09-05T00:00:00+00:00
AIRFLOW_CTX_TRY_NUMBER=1
AIRFLOW_CTX_DAG_RUN_ID=scheduled__2022-09-05T00:00:00+00:00
[2022-12-28 18:37:54,658] {taskinstance.py:1889} ERROR - Task failed with exception
Traceback (most recent call last):
  File "/home/alxavier/Documents/airflowalura/venv/lib/python3.9/site-packages/airflow/operators/python.py", line 171, in execute
    return_value = self.execute_callable()
  File "/home/alxavier/Documents/airflowalura/venv/lib/python3.9/site-packages/airflow/operators/python.py", line 189, in execute_callable
    return self.python_callable(*self.op_args, **self.op_kwargs)
  File "/home/alxavier/Documents/airflowalura/dags/dados_climaticos.py", line 27, in extrai_dados
    f'{city}/{data_interval_end}/{ds_add(data_interval_end, 7)}?unitGroup=metric&include=days&key={key}&contentType=csv')
  File "/home/alxavier/Documents/airflowalura/venv/lib/python3.9/site-packages/airflow/macros/__init__.py", line 44, in ds_add
    dt = datetime.strptime(str(ds), "%Y-%m-%d") + timedelta(days=days)
  File "/usr/lib/python3.9/_strptime.py", line 568, in _strptime_datetime
    tt, fraction, gmtoff_fraction = _strptime(data_string, format)
  File "/usr/lib/python3.9/_strptime.py", line 349, in _strptime
    raise ValueError("time data %r does not match format %r" %
ValueError: time data '2022-09_12' does not match format '%Y-%m-%d'
[2022-12-28 18:37:54,676] {taskinstance.py:1395} INFO - Marking task as FAILED. dag_id=dados_climaticos, task_id=extrai_dados, execution_date=20220905T000000, start_date=20221228T213754, end_date=20221228T213754
[2022-12-28 18:37:54,728] {standard_task_runner.py:92} ERROR - Failed to execute job 16 for task extrai_dados (time data '2022-09_12' does not match format '%Y-%m-%d'; 19442)
[2022-12-28 18:37:54,766] {local_task_job.py:156} INFO - Task exited with return code 1
[2022-12-28 18:37:54,850] {local_task_job.py:273} INFO - 0 downstream tasks scheduled from follow-on schedule check
[2022-12-28 18:42:12,276] {taskinstance.py:1159} INFO - Dependencies all met for <TaskInstance: dados_climaticos.extrai_dados scheduled__2022-09-05T00:00:00+00:00 [queued]>
[2022-12-28 18:42:12,286] {taskinstance.py:1159} INFO - Dependencies all met for <TaskInstance: dados_climaticos.extrai_dados scheduled__2022-09-05T00:00:00+00:00 [queued]>
[2022-12-28 18:42:12,287] {taskinstance.py:1356} INFO - 
--------------------------------------------------------------------------------
[2022-12-28 18:42:12,287] {taskinstance.py:1357} INFO - Starting attempt 1 of 1
[2022-12-28 18:42:12,287] {taskinstance.py:1358} INFO - 
--------------------------------------------------------------------------------
[2022-12-28 18:42:12,345] {taskinstance.py:1377} INFO - Executing <Task(PythonOperator): extrai_dados> on 2022-09-05 00:00:00+00:00
[2022-12-28 18:42:12,351] {standard_task_runner.py:52} INFO - Started process 19889 to run task
[2022-12-28 18:42:12,362] {standard_task_runner.py:79} INFO - Running: ['airflow', 'tasks', 'run', 'dados_climaticos', 'extrai_dados', 'scheduled__2022-09-05T00:00:00+00:00', '--job-id', '16', '--raw', '--subdir', 'DAGS_FOLDER/dados_climaticos.py', '--cfg-path', '/tmp/tmpnmr3ww8n', '--error-file', '/tmp/tmpmjmfcrfm']
[2022-12-28 18:42:12,374] {standard_task_runner.py:80} INFO - Job 16: Subtask extrai_dados
[2022-12-28 18:42:12,533] {task_command.py:370} INFO - Running <TaskInstance: dados_climaticos.extrai_dados scheduled__2022-09-05T00:00:00+00:00 [running]> on host alxavier-airflow
[2022-12-28 18:42:12,675] {taskinstance.py:1569} INFO - Exporting the following env vars:
AIRFLOW_CTX_DAG_OWNER=airflow
AIRFLOW_CTX_DAG_ID=dados_climaticos
AIRFLOW_CTX_TASK_ID=extrai_dados
AIRFLOW_CTX_EXECUTION_DATE=2022-09-05T00:00:00+00:00
AIRFLOW_CTX_TRY_NUMBER=1
AIRFLOW_CTX_DAG_RUN_ID=scheduled__2022-09-05T00:00:00+00:00
[2022-12-28 18:42:13,779] {taskinstance.py:1889} ERROR - Task failed with exception
Traceback (most recent call last):
  File "/home/alxavier/Documents/airflowalura/venv/lib/python3.9/site-packages/airflow/operators/python.py", line 171, in execute
    return_value = self.execute_callable()
  File "/home/alxavier/Documents/airflowalura/venv/lib/python3.9/site-packages/airflow/operators/python.py", line 189, in execute_callable
    return self.python_callable(*self.op_args, **self.op_kwargs)
  File "/home/alxavier/Documents/airflowalura/dags/dados_climaticos.py", line 33, in extrai_dados
    dados.to_csv(file_path + 'dados_brutos.csv')
  File "/home/alxavier/Documents/airflowalura/venv/lib/python3.9/site-packages/pandas/util/_decorators.py", line 211, in wrapper
    return func(*args, **kwargs)
  File "/home/alxavier/Documents/airflowalura/venv/lib/python3.9/site-packages/pandas/core/generic.py", line 3720, in to_csv
    return DataFrameRenderer(formatter).to_csv(
  File "/home/alxavier/Documents/airflowalura/venv/lib/python3.9/site-packages/pandas/util/_decorators.py", line 211, in wrapper
    return func(*args, **kwargs)
  File "/home/alxavier/Documents/airflowalura/venv/lib/python3.9/site-packages/pandas/io/formats/format.py", line 1189, in to_csv
    csv_formatter.save()
  File "/home/alxavier/Documents/airflowalura/venv/lib/python3.9/site-packages/pandas/io/formats/csvs.py", line 241, in save
    with get_handle(
  File "/home/alxavier/Documents/airflowalura/venv/lib/python3.9/site-packages/pandas/io/common.py", line 734, in get_handle
    check_parent_directory(str(handle))
  File "/home/alxavier/Documents/airflowalura/venv/lib/python3.9/site-packages/pandas/io/common.py", line 597, in check_parent_directory
    raise OSError(rf"Cannot save file into a non-existent directory: '{parent}'")
OSError: Cannot save file into a non-existent directory: '/home/alxavier/Documents/airflowalura/semana={data_interval_end}'
[2022-12-28 18:42:13,797] {taskinstance.py:1395} INFO - Marking task as FAILED. dag_id=dados_climaticos, task_id=extrai_dados, execution_date=20220905T000000, start_date=20221228T214212, end_date=20221228T214213
[2022-12-28 18:42:13,841] {standard_task_runner.py:92} ERROR - Failed to execute job 16 for task extrai_dados (Cannot save file into a non-existent directory: '/home/alxavier/Documents/airflowalura/semana={data_interval_end}'; 19889)
[2022-12-28 18:42:13,880] {local_task_job.py:156} INFO - Task exited with return code 1
[2022-12-28 18:42:13,964] {local_task_job.py:273} INFO - 0 downstream tasks scheduled from follow-on schedule check
[2022-12-28 18:44:27,326] {taskinstance.py:1159} INFO - Dependencies all met for <TaskInstance: dados_climaticos.extrai_dados scheduled__2022-09-05T00:00:00+00:00 [queued]>
[2022-12-28 18:44:27,476] {taskinstance.py:1159} INFO - Dependencies all met for <TaskInstance: dados_climaticos.extrai_dados scheduled__2022-09-05T00:00:00+00:00 [queued]>
[2022-12-28 18:44:27,492] {taskinstance.py:1356} INFO - 
--------------------------------------------------------------------------------
[2022-12-28 18:44:27,493] {taskinstance.py:1357} INFO - Starting attempt 1 of 1
[2022-12-28 18:44:27,493] {taskinstance.py:1358} INFO - 
--------------------------------------------------------------------------------
[2022-12-28 18:44:27,616] {taskinstance.py:1377} INFO - Executing <Task(PythonOperator): extrai_dados> on 2022-09-05 00:00:00+00:00
[2022-12-28 18:44:27,638] {standard_task_runner.py:52} INFO - Started process 20159 to run task
[2022-12-28 18:44:27,658] {standard_task_runner.py:79} INFO - Running: ['airflow', 'tasks', 'run', 'dados_climaticos', 'extrai_dados', 'scheduled__2022-09-05T00:00:00+00:00', '--job-id', '16', '--raw', '--subdir', 'DAGS_FOLDER/dados_climaticos.py', '--cfg-path', '/tmp/tmpglrc92x0', '--error-file', '/tmp/tmpcxd21qh6']
[2022-12-28 18:44:27,660] {standard_task_runner.py:80} INFO - Job 16: Subtask extrai_dados
[2022-12-28 18:44:27,933] {task_command.py:370} INFO - Running <TaskInstance: dados_climaticos.extrai_dados scheduled__2022-09-05T00:00:00+00:00 [running]> on host alxavier-airflow
[2022-12-28 18:44:28,113] {taskinstance.py:1569} INFO - Exporting the following env vars:
AIRFLOW_CTX_DAG_OWNER=airflow
AIRFLOW_CTX_DAG_ID=dados_climaticos
AIRFLOW_CTX_TASK_ID=extrai_dados
AIRFLOW_CTX_EXECUTION_DATE=2022-09-05T00:00:00+00:00
AIRFLOW_CTX_TRY_NUMBER=1
AIRFLOW_CTX_DAG_RUN_ID=scheduled__2022-09-05T00:00:00+00:00
[2022-12-28 18:44:29,128] {taskinstance.py:1889} ERROR - Task failed with exception
Traceback (most recent call last):
  File "/home/alxavier/Documents/airflowalura/venv/lib/python3.9/site-packages/airflow/operators/python.py", line 171, in execute
    return_value = self.execute_callable()
  File "/home/alxavier/Documents/airflowalura/venv/lib/python3.9/site-packages/airflow/operators/python.py", line 189, in execute_callable
    return self.python_callable(*self.op_args, **self.op_kwargs)
  File "/home/alxavier/Documents/airflowalura/dags/dados_climaticos.py", line 33, in extrai_dados
    dados.to_csv(file_path + 'dados_brutos.csv')
  File "/home/alxavier/Documents/airflowalura/venv/lib/python3.9/site-packages/pandas/util/_decorators.py", line 211, in wrapper
    return func(*args, **kwargs)
  File "/home/alxavier/Documents/airflowalura/venv/lib/python3.9/site-packages/pandas/core/generic.py", line 3720, in to_csv
    return DataFrameRenderer(formatter).to_csv(
  File "/home/alxavier/Documents/airflowalura/venv/lib/python3.9/site-packages/pandas/util/_decorators.py", line 211, in wrapper
    return func(*args, **kwargs)
  File "/home/alxavier/Documents/airflowalura/venv/lib/python3.9/site-packages/pandas/io/formats/format.py", line 1189, in to_csv
    csv_formatter.save()
  File "/home/alxavier/Documents/airflowalura/venv/lib/python3.9/site-packages/pandas/io/formats/csvs.py", line 241, in save
    with get_handle(
  File "/home/alxavier/Documents/airflowalura/venv/lib/python3.9/site-packages/pandas/io/common.py", line 734, in get_handle
    check_parent_directory(str(handle))
  File "/home/alxavier/Documents/airflowalura/venv/lib/python3.9/site-packages/pandas/io/common.py", line 597, in check_parent_directory
    raise OSError(rf"Cannot save file into a non-existent directory: '{parent}'")
OSError: Cannot save file into a non-existent directory: '/home/alxavier/Documents/airflowalura/semana={data_interval_end}'
[2022-12-28 18:44:29,149] {taskinstance.py:1395} INFO - Marking task as FAILED. dag_id=dados_climaticos, task_id=extrai_dados, execution_date=20220905T000000, start_date=20221228T214427, end_date=20221228T214429
[2022-12-28 18:44:29,205] {standard_task_runner.py:92} ERROR - Failed to execute job 16 for task extrai_dados (Cannot save file into a non-existent directory: '/home/alxavier/Documents/airflowalura/semana={data_interval_end}'; 20159)
[2022-12-28 18:44:29,234] {local_task_job.py:156} INFO - Task exited with return code 1
[2022-12-28 18:44:29,303] {local_task_job.py:273} INFO - 0 downstream tasks scheduled from follow-on schedule check
[2022-12-28 18:51:58,162] {taskinstance.py:1159} INFO - Dependencies all met for <TaskInstance: dados_climaticos.extrai_dados scheduled__2022-09-05T00:00:00+00:00 [queued]>
[2022-12-28 18:51:58,178] {taskinstance.py:1159} INFO - Dependencies all met for <TaskInstance: dados_climaticos.extrai_dados scheduled__2022-09-05T00:00:00+00:00 [queued]>
[2022-12-28 18:51:58,179] {taskinstance.py:1356} INFO - 
--------------------------------------------------------------------------------
[2022-12-28 18:51:58,180] {taskinstance.py:1357} INFO - Starting attempt 1 of 1
[2022-12-28 18:51:58,180] {taskinstance.py:1358} INFO - 
--------------------------------------------------------------------------------
[2022-12-28 18:51:58,242] {taskinstance.py:1377} INFO - Executing <Task(PythonOperator): extrai_dados> on 2022-09-05 00:00:00+00:00
[2022-12-28 18:51:58,255] {standard_task_runner.py:52} INFO - Started process 20976 to run task
[2022-12-28 18:51:58,260] {standard_task_runner.py:79} INFO - Running: ['airflow', 'tasks', 'run', 'dados_climaticos', 'extrai_dados', 'scheduled__2022-09-05T00:00:00+00:00', '--job-id', '16', '--raw', '--subdir', 'DAGS_FOLDER/dados_climaticos.py', '--cfg-path', '/tmp/tmpq9av_jmz', '--error-file', '/tmp/tmpd7j_5om6']
[2022-12-28 18:51:58,265] {standard_task_runner.py:80} INFO - Job 16: Subtask extrai_dados
[2022-12-28 18:51:58,434] {task_command.py:370} INFO - Running <TaskInstance: dados_climaticos.extrai_dados scheduled__2022-09-05T00:00:00+00:00 [running]> on host alxavier-airflow
[2022-12-28 18:51:58,565] {taskinstance.py:1569} INFO - Exporting the following env vars:
AIRFLOW_CTX_DAG_OWNER=airflow
AIRFLOW_CTX_DAG_ID=dados_climaticos
AIRFLOW_CTX_TASK_ID=extrai_dados
AIRFLOW_CTX_EXECUTION_DATE=2022-09-05T00:00:00+00:00
AIRFLOW_CTX_TRY_NUMBER=1
AIRFLOW_CTX_DAG_RUN_ID=scheduled__2022-09-05T00:00:00+00:00
[2022-12-28 18:51:59,813] {python.py:173} INFO - Done. Returned value was: None
[2022-12-28 18:51:59,841] {taskinstance.py:1395} INFO - Marking task as SUCCESS. dag_id=dados_climaticos, task_id=extrai_dados, execution_date=20220905T000000, start_date=20221228T215158, end_date=20221228T215159
[2022-12-28 18:51:59,895] {local_task_job.py:156} INFO - Task exited with return code 0
[2022-12-28 18:51:59,950] {local_task_job.py:273} INFO - 0 downstream tasks scheduled from follow-on schedule check
