[2022-12-28 17:50:28,621] {taskinstance.py:1159} INFO - Dependencies all met for <TaskInstance: dados_climaticos.cria_pasta scheduled__2022-12-05T00:00:00+00:00 [queued]>
[2022-12-28 17:50:28,651] {taskinstance.py:1159} INFO - Dependencies all met for <TaskInstance: dados_climaticos.cria_pasta scheduled__2022-12-05T00:00:00+00:00 [queued]>
[2022-12-28 17:50:28,652] {taskinstance.py:1356} INFO - 
--------------------------------------------------------------------------------
[2022-12-28 17:50:28,652] {taskinstance.py:1357} INFO - Starting attempt 1 of 1
[2022-12-28 17:50:28,652] {taskinstance.py:1358} INFO - 
--------------------------------------------------------------------------------
[2022-12-28 17:50:28,699] {taskinstance.py:1377} INFO - Executing <Task(BashOperator): cria_pasta> on 2022-12-05 00:00:00+00:00
[2022-12-28 17:50:28,705] {standard_task_runner.py:52} INFO - Started process 14316 to run task
[2022-12-28 17:50:28,717] {standard_task_runner.py:79} INFO - Running: ['airflow', 'tasks', 'run', 'dados_climaticos', 'cria_pasta', 'scheduled__2022-12-05T00:00:00+00:00', '--job-id', '26', '--raw', '--subdir', 'DAGS_FOLDER/dados_climaticos.py', '--cfg-path', '/tmp/tmp4jzgyemv', '--error-file', '/tmp/tmp3kixsc4y']
[2022-12-28 17:50:28,721] {standard_task_runner.py:80} INFO - Job 26: Subtask cria_pasta
[2022-12-28 17:50:28,870] {task_command.py:370} INFO - Running <TaskInstance: dados_climaticos.cria_pasta scheduled__2022-12-05T00:00:00+00:00 [running]> on host alxavier-airflow
[2022-12-28 17:50:28,946] {taskinstance.py:1889} ERROR - Task failed with exception
Traceback (most recent call last):
  File "/home/alxavier/Documents/airflowalura/venv/lib/python3.9/site-packages/airflow/models/taskinstance.py", line 1451, in _run_raw_task
    self._execute_task_with_callbacks(context, test_mode)
  File "/home/alxavier/Documents/airflowalura/venv/lib/python3.9/site-packages/airflow/models/taskinstance.py", line 1555, in _execute_task_with_callbacks
    task_orig = self.render_templates(context=context)
  File "/home/alxavier/Documents/airflowalura/venv/lib/python3.9/site-packages/airflow/models/taskinstance.py", line 2212, in render_templates
    rendered_task = self.task.render_template_fields(context)
  File "/home/alxavier/Documents/airflowalura/venv/lib/python3.9/site-packages/airflow/models/baseoperator.py", line 1185, in render_template_fields
    self._do_render_template_fields(self, self.template_fields, context, jinja_env, set())
  File "/home/alxavier/Documents/airflowalura/venv/lib/python3.9/site-packages/airflow/utils/session.py", line 71, in wrapper
    return func(*args, session=session, **kwargs)
  File "/home/alxavier/Documents/airflowalura/venv/lib/python3.9/site-packages/airflow/models/abstractoperator.py", line 344, in _do_render_template_fields
    rendered_content = self.render_template(
  File "/home/alxavier/Documents/airflowalura/venv/lib/python3.9/site-packages/airflow/models/abstractoperator.py", line 387, in render_template
    template = jinja_env.from_string(value)
  File "/home/alxavier/Documents/airflowalura/venv/lib/python3.9/site-packages/jinja2/environment.py", line 1092, in from_string
    return cls.from_code(self, self.compile(source), gs, None)
  File "/home/alxavier/Documents/airflowalura/venv/lib/python3.9/site-packages/jinja2/environment.py", line 757, in compile
    self.handle_exception(source=source_hint)
  File "/home/alxavier/Documents/airflowalura/venv/lib/python3.9/site-packages/jinja2/environment.py", line 925, in handle_exception
    raise rewrite_traceback_stack(source=source)
  File "<unknown>", line 1, in template
jinja2.exceptions.TemplateSyntaxError: unexpected end of template, expected ','.
[2022-12-28 17:50:28,963] {taskinstance.py:1395} INFO - Marking task as FAILED. dag_id=dados_climaticos, task_id=cria_pasta, execution_date=20221205T000000, start_date=20221228T205028, end_date=20221228T205028
[2022-12-28 17:50:29,014] {standard_task_runner.py:92} ERROR - Failed to execute job 26 for task cria_pasta (unexpected end of template, expected ','.; 14316)
[2022-12-28 17:50:29,035] {local_task_job.py:156} INFO - Task exited with return code 1
[2022-12-28 17:50:29,158] {local_task_job.py:273} INFO - 0 downstream tasks scheduled from follow-on schedule check
[2022-12-28 18:14:57,489] {taskinstance.py:1159} INFO - Dependencies all met for <TaskInstance: dados_climaticos.cria_pasta scheduled__2022-12-05T00:00:00+00:00 [queued]>
[2022-12-28 18:14:57,501] {taskinstance.py:1159} INFO - Dependencies all met for <TaskInstance: dados_climaticos.cria_pasta scheduled__2022-12-05T00:00:00+00:00 [queued]>
[2022-12-28 18:14:57,501] {taskinstance.py:1356} INFO - 
--------------------------------------------------------------------------------
[2022-12-28 18:14:57,501] {taskinstance.py:1357} INFO - Starting attempt 1 of 1
[2022-12-28 18:14:57,501] {taskinstance.py:1358} INFO - 
--------------------------------------------------------------------------------
[2022-12-28 18:14:57,542] {taskinstance.py:1377} INFO - Executing <Task(BashOperator): cria_pasta> on 2022-12-05 00:00:00+00:00
[2022-12-28 18:14:57,550] {standard_task_runner.py:52} INFO - Started process 16941 to run task
[2022-12-28 18:14:57,574] {standard_task_runner.py:79} INFO - Running: ['airflow', 'tasks', 'run', 'dados_climaticos', 'cria_pasta', 'scheduled__2022-12-05T00:00:00+00:00', '--job-id', '26', '--raw', '--subdir', 'DAGS_FOLDER/dados_climaticos.py', '--cfg-path', '/tmp/tmppj2eppdc', '--error-file', '/tmp/tmpfkjw0ii9']
[2022-12-28 18:14:57,576] {standard_task_runner.py:80} INFO - Job 26: Subtask cria_pasta
[2022-12-28 18:14:57,728] {task_command.py:370} INFO - Running <TaskInstance: dados_climaticos.cria_pasta scheduled__2022-12-05T00:00:00+00:00 [running]> on host alxavier-airflow
[2022-12-28 18:14:57,799] {taskinstance.py:1889} ERROR - Task failed with exception
Traceback (most recent call last):
  File "/home/alxavier/Documents/airflowalura/venv/lib/python3.9/site-packages/airflow/models/taskinstance.py", line 1451, in _run_raw_task
    self._execute_task_with_callbacks(context, test_mode)
  File "/home/alxavier/Documents/airflowalura/venv/lib/python3.9/site-packages/airflow/models/taskinstance.py", line 1555, in _execute_task_with_callbacks
    task_orig = self.render_templates(context=context)
  File "/home/alxavier/Documents/airflowalura/venv/lib/python3.9/site-packages/airflow/models/taskinstance.py", line 2212, in render_templates
    rendered_task = self.task.render_template_fields(context)
  File "/home/alxavier/Documents/airflowalura/venv/lib/python3.9/site-packages/airflow/models/baseoperator.py", line 1185, in render_template_fields
    self._do_render_template_fields(self, self.template_fields, context, jinja_env, set())
  File "/home/alxavier/Documents/airflowalura/venv/lib/python3.9/site-packages/airflow/utils/session.py", line 71, in wrapper
    return func(*args, session=session, **kwargs)
  File "/home/alxavier/Documents/airflowalura/venv/lib/python3.9/site-packages/airflow/models/abstractoperator.py", line 344, in _do_render_template_fields
    rendered_content = self.render_template(
  File "/home/alxavier/Documents/airflowalura/venv/lib/python3.9/site-packages/airflow/models/abstractoperator.py", line 387, in render_template
    template = jinja_env.from_string(value)
  File "/home/alxavier/Documents/airflowalura/venv/lib/python3.9/site-packages/jinja2/environment.py", line 1092, in from_string
    return cls.from_code(self, self.compile(source), gs, None)
  File "/home/alxavier/Documents/airflowalura/venv/lib/python3.9/site-packages/jinja2/environment.py", line 757, in compile
    self.handle_exception(source=source_hint)
  File "/home/alxavier/Documents/airflowalura/venv/lib/python3.9/site-packages/jinja2/environment.py", line 925, in handle_exception
    raise rewrite_traceback_stack(source=source)
  File "<unknown>", line 1, in template
jinja2.exceptions.TemplateSyntaxError: unexpected end of template, expected ','.
[2022-12-28 18:14:57,811] {taskinstance.py:1395} INFO - Marking task as FAILED. dag_id=dados_climaticos, task_id=cria_pasta, execution_date=20221205T000000, start_date=20221228T211457, end_date=20221228T211457
[2022-12-28 18:14:57,846] {standard_task_runner.py:92} ERROR - Failed to execute job 26 for task cria_pasta (unexpected end of template, expected ','.; 16941)
[2022-12-28 18:14:57,887] {local_task_job.py:156} INFO - Task exited with return code 1
[2022-12-28 18:14:57,954] {local_task_job.py:273} INFO - 0 downstream tasks scheduled from follow-on schedule check
[2022-12-28 18:30:17,250] {taskinstance.py:1159} INFO - Dependencies all met for <TaskInstance: dados_climaticos.cria_pasta scheduled__2022-12-05T00:00:00+00:00 [queued]>
[2022-12-28 18:30:17,277] {taskinstance.py:1159} INFO - Dependencies all met for <TaskInstance: dados_climaticos.cria_pasta scheduled__2022-12-05T00:00:00+00:00 [queued]>
[2022-12-28 18:30:17,277] {taskinstance.py:1356} INFO - 
--------------------------------------------------------------------------------
[2022-12-28 18:30:17,278] {taskinstance.py:1357} INFO - Starting attempt 1 of 1
[2022-12-28 18:30:17,279] {taskinstance.py:1358} INFO - 
--------------------------------------------------------------------------------
[2022-12-28 18:30:17,328] {taskinstance.py:1377} INFO - Executing <Task(BashOperator): cria_pasta> on 2022-12-05 00:00:00+00:00
[2022-12-28 18:30:17,334] {standard_task_runner.py:52} INFO - Started process 18623 to run task
[2022-12-28 18:30:17,352] {standard_task_runner.py:79} INFO - Running: ['airflow', 'tasks', 'run', 'dados_climaticos', 'cria_pasta', 'scheduled__2022-12-05T00:00:00+00:00', '--job-id', '40', '--raw', '--subdir', 'DAGS_FOLDER/dados_climaticos.py', '--cfg-path', '/tmp/tmp_y78filo', '--error-file', '/tmp/tmpling8l5c']
[2022-12-28 18:30:17,365] {standard_task_runner.py:80} INFO - Job 40: Subtask cria_pasta
[2022-12-28 18:30:17,513] {task_command.py:370} INFO - Running <TaskInstance: dados_climaticos.cria_pasta scheduled__2022-12-05T00:00:00+00:00 [running]> on host alxavier-airflow
[2022-12-28 18:30:17,680] {taskinstance.py:1569} INFO - Exporting the following env vars:
AIRFLOW_CTX_DAG_OWNER=airflow
AIRFLOW_CTX_DAG_ID=dados_climaticos
AIRFLOW_CTX_TASK_ID=cria_pasta
AIRFLOW_CTX_EXECUTION_DATE=2022-12-05T00:00:00+00:00
AIRFLOW_CTX_TRY_NUMBER=1
AIRFLOW_CTX_DAG_RUN_ID=scheduled__2022-12-05T00:00:00+00:00
[2022-12-28 18:30:17,688] {subprocess.py:62} INFO - Tmp dir root location: 
 /tmp
[2022-12-28 18:30:17,694] {subprocess.py:74} INFO - Running command: ['bash', '-c', 'mkdir -p "/home/alxavier/Documents/airflowalura/semana=2022-12-12"']
[2022-12-28 18:30:17,713] {subprocess.py:85} INFO - Output:
[2022-12-28 18:30:17,725] {subprocess.py:96} INFO - Command exited with return code 0
[2022-12-28 18:30:17,829] {taskinstance.py:1395} INFO - Marking task as SUCCESS. dag_id=dados_climaticos, task_id=cria_pasta, execution_date=20221205T000000, start_date=20221228T213017, end_date=20221228T213017
[2022-12-28 18:30:17,920] {local_task_job.py:156} INFO - Task exited with return code 0
[2022-12-28 18:30:18,050] {local_task_job.py:273} INFO - 1 downstream tasks scheduled from follow-on schedule check
[2022-12-28 18:54:21,509] {taskinstance.py:1159} INFO - Dependencies all met for <TaskInstance: dados_climaticos.cria_pasta scheduled__2022-12-05T00:00:00+00:00 [queued]>
[2022-12-28 18:54:21,528] {taskinstance.py:1159} INFO - Dependencies all met for <TaskInstance: dados_climaticos.cria_pasta scheduled__2022-12-05T00:00:00+00:00 [queued]>
[2022-12-28 18:54:21,528] {taskinstance.py:1356} INFO - 
--------------------------------------------------------------------------------
[2022-12-28 18:54:21,528] {taskinstance.py:1357} INFO - Starting attempt 1 of 1
[2022-12-28 18:54:21,529] {taskinstance.py:1358} INFO - 
--------------------------------------------------------------------------------
[2022-12-28 18:54:21,561] {taskinstance.py:1377} INFO - Executing <Task(BashOperator): cria_pasta> on 2022-12-05 00:00:00+00:00
[2022-12-28 18:54:21,567] {standard_task_runner.py:52} INFO - Started process 21248 to run task
[2022-12-28 18:54:21,578] {standard_task_runner.py:79} INFO - Running: ['airflow', 'tasks', 'run', 'dados_climaticos', 'cria_pasta', 'scheduled__2022-12-05T00:00:00+00:00', '--job-id', '41', '--raw', '--subdir', 'DAGS_FOLDER/dados_climaticos.py', '--cfg-path', '/tmp/tmpc2zyeowc', '--error-file', '/tmp/tmprmhx9cll']
[2022-12-28 18:54:21,582] {standard_task_runner.py:80} INFO - Job 41: Subtask cria_pasta
[2022-12-28 18:54:21,670] {task_command.py:370} INFO - Running <TaskInstance: dados_climaticos.cria_pasta scheduled__2022-12-05T00:00:00+00:00 [running]> on host alxavier-airflow
[2022-12-28 18:54:21,786] {taskinstance.py:1569} INFO - Exporting the following env vars:
AIRFLOW_CTX_DAG_OWNER=airflow
AIRFLOW_CTX_DAG_ID=dados_climaticos
AIRFLOW_CTX_TASK_ID=cria_pasta
AIRFLOW_CTX_EXECUTION_DATE=2022-12-05T00:00:00+00:00
AIRFLOW_CTX_TRY_NUMBER=1
AIRFLOW_CTX_DAG_RUN_ID=scheduled__2022-12-05T00:00:00+00:00
[2022-12-28 18:54:21,788] {subprocess.py:62} INFO - Tmp dir root location: 
 /tmp
[2022-12-28 18:54:21,788] {subprocess.py:74} INFO - Running command: ['bash', '-c', 'mkdir -p "/home/alxavier/Documents/airflowalura/semana=2022-12-12"']
[2022-12-28 18:54:21,805] {subprocess.py:85} INFO - Output:
[2022-12-28 18:54:21,816] {subprocess.py:96} INFO - Command exited with return code 0
[2022-12-28 18:54:21,922] {taskinstance.py:1395} INFO - Marking task as SUCCESS. dag_id=dados_climaticos, task_id=cria_pasta, execution_date=20221205T000000, start_date=20221228T215421, end_date=20221228T215421
[2022-12-28 18:54:21,984] {local_task_job.py:156} INFO - Task exited with return code 0
[2022-12-28 18:54:22,042] {local_task_job.py:273} INFO - 1 downstream tasks scheduled from follow-on schedule check
