[2022-12-28 18:29:00,695] {taskinstance.py:1159} INFO - Dependencies all met for <TaskInstance: dados_climaticos.extrai_dados scheduled__2022-09-26T00:00:00+00:00 [queued]>
[2022-12-28 18:29:00,705] {taskinstance.py:1159} INFO - Dependencies all met for <TaskInstance: dados_climaticos.extrai_dados scheduled__2022-09-26T00:00:00+00:00 [queued]>
[2022-12-28 18:29:00,705] {taskinstance.py:1356} INFO - 
--------------------------------------------------------------------------------
[2022-12-28 18:29:00,706] {taskinstance.py:1357} INFO - Starting attempt 1 of 1
[2022-12-28 18:29:00,707] {taskinstance.py:1358} INFO - 
--------------------------------------------------------------------------------
[2022-12-28 18:29:00,778] {taskinstance.py:1377} INFO - Executing <Task(PythonOperator): extrai_dados> on 2022-09-26 00:00:00+00:00
[2022-12-28 18:29:00,785] {standard_task_runner.py:52} INFO - Started process 18479 to run task
[2022-12-28 18:29:00,797] {standard_task_runner.py:79} INFO - Running: ['airflow', 'tasks', 'run', 'dados_climaticos', 'extrai_dados', 'scheduled__2022-09-26T00:00:00+00:00', '--job-id', '23', '--raw', '--subdir', 'DAGS_FOLDER/dados_climaticos.py', '--cfg-path', '/tmp/tmpjye5z2vl', '--error-file', '/tmp/tmpj_fdnjvg']
[2022-12-28 18:29:00,799] {standard_task_runner.py:80} INFO - Job 23: Subtask extrai_dados
[2022-12-28 18:29:00,977] {task_command.py:370} INFO - Running <TaskInstance: dados_climaticos.extrai_dados scheduled__2022-09-26T00:00:00+00:00 [running]> on host alxavier-airflow
[2022-12-28 18:29:01,042] {taskinstance.py:1889} ERROR - Task failed with exception
Traceback (most recent call last):
  File "/home/alxavier/Documents/airflowalura/venv/lib/python3.9/site-packages/airflow/models/taskinstance.py", line 1451, in _run_raw_task
    self._execute_task_with_callbacks(context, test_mode)
  File "/home/alxavier/Documents/airflowalura/venv/lib/python3.9/site-packages/airflow/models/taskinstance.py", line 1555, in _execute_task_with_callbacks
    task_orig = self.render_templates(context=context)
  File "/home/alxavier/Documents/airflowalura/venv/lib/python3.9/site-packages/airflow/models/taskinstance.py", line 2212, in render_templates
    rendered_task = self.task.render_template_fields(context)
  File "/home/alxavier/Documents/airflowalura/venv/lib/python3.9/site-packages/airflow/models/baseoperator.py", line 1185, in render_template_fields
    self._do_render_template_fields(self, self.template_fields, context, jinja_env, set())
  File "/home/alxavier/Documents/airflowalura/venv/lib/python3.9/site-packages/airflow/utils/session.py", line 71, in wrapper
    return func(*args, session=session, **kwargs)
  File "/home/alxavier/Documents/airflowalura/venv/lib/python3.9/site-packages/airflow/models/abstractoperator.py", line 344, in _do_render_template_fields
    rendered_content = self.render_template(
  File "/home/alxavier/Documents/airflowalura/venv/lib/python3.9/site-packages/airflow/models/abstractoperator.py", line 404, in render_template
    return {key: self.render_template(value, context, jinja_env) for key, value in value.items()}
  File "/home/alxavier/Documents/airflowalura/venv/lib/python3.9/site-packages/airflow/models/abstractoperator.py", line 404, in <dictcomp>
    return {key: self.render_template(value, context, jinja_env) for key, value in value.items()}
  File "/home/alxavier/Documents/airflowalura/venv/lib/python3.9/site-packages/airflow/models/abstractoperator.py", line 387, in render_template
    template = jinja_env.from_string(value)
  File "/home/alxavier/Documents/airflowalura/venv/lib/python3.9/site-packages/jinja2/environment.py", line 1092, in from_string
    return cls.from_code(self, self.compile(source), gs, None)
  File "/home/alxavier/Documents/airflowalura/venv/lib/python3.9/site-packages/jinja2/environment.py", line 757, in compile
    self.handle_exception(source=source_hint)
  File "/home/alxavier/Documents/airflowalura/venv/lib/python3.9/site-packages/jinja2/environment.py", line 925, in handle_exception
    raise rewrite_traceback_stack(source=source)
  File "<unknown>", line 1, in template
jinja2.exceptions.TemplateSyntaxError: unexpected char '"' at 29
[2022-12-28 18:29:01,052] {taskinstance.py:1395} INFO - Marking task as FAILED. dag_id=dados_climaticos, task_id=extrai_dados, execution_date=20220926T000000, start_date=20221228T212900, end_date=20221228T212901
[2022-12-28 18:29:01,086] {standard_task_runner.py:92} ERROR - Failed to execute job 23 for task extrai_dados (unexpected char '"' at 29; 18479)
[2022-12-28 18:29:01,136] {local_task_job.py:156} INFO - Task exited with return code 1
[2022-12-28 18:29:01,228] {local_task_job.py:273} INFO - 0 downstream tasks scheduled from follow-on schedule check
[2022-12-28 18:38:34,542] {taskinstance.py:1159} INFO - Dependencies all met for <TaskInstance: dados_climaticos.extrai_dados scheduled__2022-09-26T00:00:00+00:00 [queued]>
[2022-12-28 18:38:34,556] {taskinstance.py:1159} INFO - Dependencies all met for <TaskInstance: dados_climaticos.extrai_dados scheduled__2022-09-26T00:00:00+00:00 [queued]>
[2022-12-28 18:38:34,556] {taskinstance.py:1356} INFO - 
--------------------------------------------------------------------------------
[2022-12-28 18:38:34,556] {taskinstance.py:1357} INFO - Starting attempt 1 of 1
[2022-12-28 18:38:34,556] {taskinstance.py:1358} INFO - 
--------------------------------------------------------------------------------
[2022-12-28 18:38:34,625] {taskinstance.py:1377} INFO - Executing <Task(PythonOperator): extrai_dados> on 2022-09-26 00:00:00+00:00
[2022-12-28 18:38:34,637] {standard_task_runner.py:52} INFO - Started process 19507 to run task
[2022-12-28 18:38:34,650] {standard_task_runner.py:79} INFO - Running: ['airflow', 'tasks', 'run', 'dados_climaticos', 'extrai_dados', 'scheduled__2022-09-26T00:00:00+00:00', '--job-id', '23', '--raw', '--subdir', 'DAGS_FOLDER/dados_climaticos.py', '--cfg-path', '/tmp/tmpz3zqwez0', '--error-file', '/tmp/tmp149pgqor']
[2022-12-28 18:38:34,652] {standard_task_runner.py:80} INFO - Job 23: Subtask extrai_dados
[2022-12-28 18:38:34,756] {task_command.py:370} INFO - Running <TaskInstance: dados_climaticos.extrai_dados scheduled__2022-09-26T00:00:00+00:00 [running]> on host alxavier-airflow
[2022-12-28 18:38:34,856] {taskinstance.py:1569} INFO - Exporting the following env vars:
AIRFLOW_CTX_DAG_OWNER=airflow
AIRFLOW_CTX_DAG_ID=dados_climaticos
AIRFLOW_CTX_TASK_ID=extrai_dados
AIRFLOW_CTX_EXECUTION_DATE=2022-09-26T00:00:00+00:00
AIRFLOW_CTX_TRY_NUMBER=1
AIRFLOW_CTX_DAG_RUN_ID=scheduled__2022-09-26T00:00:00+00:00
[2022-12-28 18:38:34,859] {taskinstance.py:1889} ERROR - Task failed with exception
Traceback (most recent call last):
  File "/home/alxavier/Documents/airflowalura/venv/lib/python3.9/site-packages/airflow/operators/python.py", line 171, in execute
    return_value = self.execute_callable()
  File "/home/alxavier/Documents/airflowalura/venv/lib/python3.9/site-packages/airflow/operators/python.py", line 189, in execute_callable
    return self.python_callable(*self.op_args, **self.op_kwargs)
  File "/home/alxavier/Documents/airflowalura/dags/dados_climaticos.py", line 27, in extrai_dados
    f'{city}/{data_interval_end}/{ds_add(data_interval_end, 7)}?unitGroup=metric&include=days&key={key}&contentType=csv')
  File "/home/alxavier/Documents/airflowalura/venv/lib/python3.9/site-packages/airflow/macros/__init__.py", line 44, in ds_add
    dt = datetime.strptime(str(ds), "%Y-%m-%d") + timedelta(days=days)
  File "/usr/lib/python3.9/_strptime.py", line 568, in _strptime_datetime
    tt, fraction, gmtoff_fraction = _strptime(data_string, format)
  File "/usr/lib/python3.9/_strptime.py", line 349, in _strptime
    raise ValueError("time data %r does not match format %r" %
ValueError: time data '2022-10_03' does not match format '%Y-%m-%d'
[2022-12-28 18:38:34,867] {taskinstance.py:1395} INFO - Marking task as FAILED. dag_id=dados_climaticos, task_id=extrai_dados, execution_date=20220926T000000, start_date=20221228T213834, end_date=20221228T213834
[2022-12-28 18:38:34,904] {standard_task_runner.py:92} ERROR - Failed to execute job 23 for task extrai_dados (time data '2022-10_03' does not match format '%Y-%m-%d'; 19507)
[2022-12-28 18:38:34,920] {local_task_job.py:156} INFO - Task exited with return code 1
[2022-12-28 18:38:34,957] {local_task_job.py:273} INFO - 0 downstream tasks scheduled from follow-on schedule check
[2022-12-28 18:42:48,849] {taskinstance.py:1159} INFO - Dependencies all met for <TaskInstance: dados_climaticos.extrai_dados scheduled__2022-09-26T00:00:00+00:00 [queued]>
[2022-12-28 18:42:48,862] {taskinstance.py:1159} INFO - Dependencies all met for <TaskInstance: dados_climaticos.extrai_dados scheduled__2022-09-26T00:00:00+00:00 [queued]>
[2022-12-28 18:42:48,863] {taskinstance.py:1356} INFO - 
--------------------------------------------------------------------------------
[2022-12-28 18:42:48,863] {taskinstance.py:1357} INFO - Starting attempt 1 of 1
[2022-12-28 18:42:48,863] {taskinstance.py:1358} INFO - 
--------------------------------------------------------------------------------
[2022-12-28 18:42:48,899] {taskinstance.py:1377} INFO - Executing <Task(PythonOperator): extrai_dados> on 2022-09-26 00:00:00+00:00
[2022-12-28 18:42:48,905] {standard_task_runner.py:52} INFO - Started process 19948 to run task
[2022-12-28 18:42:48,921] {standard_task_runner.py:79} INFO - Running: ['airflow', 'tasks', 'run', 'dados_climaticos', 'extrai_dados', 'scheduled__2022-09-26T00:00:00+00:00', '--job-id', '22', '--raw', '--subdir', 'DAGS_FOLDER/dados_climaticos.py', '--cfg-path', '/tmp/tmp7sggob0_', '--error-file', '/tmp/tmpkb28w1n2']
[2022-12-28 18:42:48,923] {standard_task_runner.py:80} INFO - Job 22: Subtask extrai_dados
[2022-12-28 18:42:49,046] {task_command.py:370} INFO - Running <TaskInstance: dados_climaticos.extrai_dados scheduled__2022-09-26T00:00:00+00:00 [running]> on host alxavier-airflow
[2022-12-28 18:42:49,217] {taskinstance.py:1569} INFO - Exporting the following env vars:
AIRFLOW_CTX_DAG_OWNER=airflow
AIRFLOW_CTX_DAG_ID=dados_climaticos
AIRFLOW_CTX_TASK_ID=extrai_dados
AIRFLOW_CTX_EXECUTION_DATE=2022-09-26T00:00:00+00:00
AIRFLOW_CTX_TRY_NUMBER=1
AIRFLOW_CTX_DAG_RUN_ID=scheduled__2022-09-26T00:00:00+00:00
[2022-12-28 18:42:50,215] {taskinstance.py:1889} ERROR - Task failed with exception
Traceback (most recent call last):
  File "/home/alxavier/Documents/airflowalura/venv/lib/python3.9/site-packages/airflow/operators/python.py", line 171, in execute
    return_value = self.execute_callable()
  File "/home/alxavier/Documents/airflowalura/venv/lib/python3.9/site-packages/airflow/operators/python.py", line 189, in execute_callable
    return self.python_callable(*self.op_args, **self.op_kwargs)
  File "/home/alxavier/Documents/airflowalura/dags/dados_climaticos.py", line 33, in extrai_dados
    dados.to_csv(file_path + 'dados_brutos.csv')
  File "/home/alxavier/Documents/airflowalura/venv/lib/python3.9/site-packages/pandas/util/_decorators.py", line 211, in wrapper
    return func(*args, **kwargs)
  File "/home/alxavier/Documents/airflowalura/venv/lib/python3.9/site-packages/pandas/core/generic.py", line 3720, in to_csv
    return DataFrameRenderer(formatter).to_csv(
  File "/home/alxavier/Documents/airflowalura/venv/lib/python3.9/site-packages/pandas/util/_decorators.py", line 211, in wrapper
    return func(*args, **kwargs)
  File "/home/alxavier/Documents/airflowalura/venv/lib/python3.9/site-packages/pandas/io/formats/format.py", line 1189, in to_csv
    csv_formatter.save()
  File "/home/alxavier/Documents/airflowalura/venv/lib/python3.9/site-packages/pandas/io/formats/csvs.py", line 241, in save
    with get_handle(
  File "/home/alxavier/Documents/airflowalura/venv/lib/python3.9/site-packages/pandas/io/common.py", line 734, in get_handle
    check_parent_directory(str(handle))
  File "/home/alxavier/Documents/airflowalura/venv/lib/python3.9/site-packages/pandas/io/common.py", line 597, in check_parent_directory
    raise OSError(rf"Cannot save file into a non-existent directory: '{parent}'")
OSError: Cannot save file into a non-existent directory: '/home/alxavier/Documents/airflowalura/semana={data_interval_end}'
[2022-12-28 18:42:50,236] {taskinstance.py:1395} INFO - Marking task as FAILED. dag_id=dados_climaticos, task_id=extrai_dados, execution_date=20220926T000000, start_date=20221228T214248, end_date=20221228T214250
[2022-12-28 18:42:50,277] {standard_task_runner.py:92} ERROR - Failed to execute job 22 for task extrai_dados (Cannot save file into a non-existent directory: '/home/alxavier/Documents/airflowalura/semana={data_interval_end}'; 19948)
[2022-12-28 18:42:50,322] {local_task_job.py:156} INFO - Task exited with return code 1
[2022-12-28 18:42:50,461] {local_task_job.py:273} INFO - 0 downstream tasks scheduled from follow-on schedule check
[2022-12-28 18:45:03,775] {taskinstance.py:1159} INFO - Dependencies all met for <TaskInstance: dados_climaticos.extrai_dados scheduled__2022-09-26T00:00:00+00:00 [queued]>
[2022-12-28 18:45:03,800] {taskinstance.py:1159} INFO - Dependencies all met for <TaskInstance: dados_climaticos.extrai_dados scheduled__2022-09-26T00:00:00+00:00 [queued]>
[2022-12-28 18:45:03,801] {taskinstance.py:1356} INFO - 
--------------------------------------------------------------------------------
[2022-12-28 18:45:03,803] {taskinstance.py:1357} INFO - Starting attempt 1 of 1
[2022-12-28 18:45:03,804] {taskinstance.py:1358} INFO - 
--------------------------------------------------------------------------------
[2022-12-28 18:45:03,869] {taskinstance.py:1377} INFO - Executing <Task(PythonOperator): extrai_dados> on 2022-09-26 00:00:00+00:00
[2022-12-28 18:45:03,893] {standard_task_runner.py:52} INFO - Started process 20219 to run task
[2022-12-28 18:45:03,920] {standard_task_runner.py:79} INFO - Running: ['airflow', 'tasks', 'run', 'dados_climaticos', 'extrai_dados', 'scheduled__2022-09-26T00:00:00+00:00', '--job-id', '22', '--raw', '--subdir', 'DAGS_FOLDER/dados_climaticos.py', '--cfg-path', '/tmp/tmpz6ytnr4n', '--error-file', '/tmp/tmpevhbvh5j']
[2022-12-28 18:45:03,926] {standard_task_runner.py:80} INFO - Job 22: Subtask extrai_dados
[2022-12-28 18:45:04,085] {task_command.py:370} INFO - Running <TaskInstance: dados_climaticos.extrai_dados scheduled__2022-09-26T00:00:00+00:00 [running]> on host alxavier-airflow
[2022-12-28 18:45:04,249] {taskinstance.py:1569} INFO - Exporting the following env vars:
AIRFLOW_CTX_DAG_OWNER=airflow
AIRFLOW_CTX_DAG_ID=dados_climaticos
AIRFLOW_CTX_TASK_ID=extrai_dados
AIRFLOW_CTX_EXECUTION_DATE=2022-09-26T00:00:00+00:00
AIRFLOW_CTX_TRY_NUMBER=1
AIRFLOW_CTX_DAG_RUN_ID=scheduled__2022-09-26T00:00:00+00:00
[2022-12-28 18:45:05,173] {taskinstance.py:1889} ERROR - Task failed with exception
Traceback (most recent call last):
  File "/home/alxavier/Documents/airflowalura/venv/lib/python3.9/site-packages/airflow/operators/python.py", line 171, in execute
    return_value = self.execute_callable()
  File "/home/alxavier/Documents/airflowalura/venv/lib/python3.9/site-packages/airflow/operators/python.py", line 189, in execute_callable
    return self.python_callable(*self.op_args, **self.op_kwargs)
  File "/home/alxavier/Documents/airflowalura/dags/dados_climaticos.py", line 33, in extrai_dados
    dados.to_csv(file_path + 'dados_brutos.csv')
  File "/home/alxavier/Documents/airflowalura/venv/lib/python3.9/site-packages/pandas/util/_decorators.py", line 211, in wrapper
    return func(*args, **kwargs)
  File "/home/alxavier/Documents/airflowalura/venv/lib/python3.9/site-packages/pandas/core/generic.py", line 3720, in to_csv
    return DataFrameRenderer(formatter).to_csv(
  File "/home/alxavier/Documents/airflowalura/venv/lib/python3.9/site-packages/pandas/util/_decorators.py", line 211, in wrapper
    return func(*args, **kwargs)
  File "/home/alxavier/Documents/airflowalura/venv/lib/python3.9/site-packages/pandas/io/formats/format.py", line 1189, in to_csv
    csv_formatter.save()
  File "/home/alxavier/Documents/airflowalura/venv/lib/python3.9/site-packages/pandas/io/formats/csvs.py", line 241, in save
    with get_handle(
  File "/home/alxavier/Documents/airflowalura/venv/lib/python3.9/site-packages/pandas/io/common.py", line 734, in get_handle
    check_parent_directory(str(handle))
  File "/home/alxavier/Documents/airflowalura/venv/lib/python3.9/site-packages/pandas/io/common.py", line 597, in check_parent_directory
    raise OSError(rf"Cannot save file into a non-existent directory: '{parent}'")
OSError: Cannot save file into a non-existent directory: '/home/alxavier/Documents/airflowalura/semana={data_interval_end}'
[2022-12-28 18:45:05,188] {taskinstance.py:1395} INFO - Marking task as FAILED. dag_id=dados_climaticos, task_id=extrai_dados, execution_date=20220926T000000, start_date=20221228T214503, end_date=20221228T214505
[2022-12-28 18:45:05,235] {standard_task_runner.py:92} ERROR - Failed to execute job 22 for task extrai_dados (Cannot save file into a non-existent directory: '/home/alxavier/Documents/airflowalura/semana={data_interval_end}'; 20219)
[2022-12-28 18:45:05,283] {local_task_job.py:156} INFO - Task exited with return code 1
[2022-12-28 18:45:05,362] {local_task_job.py:273} INFO - 0 downstream tasks scheduled from follow-on schedule check
[2022-12-28 18:52:32,226] {taskinstance.py:1159} INFO - Dependencies all met for <TaskInstance: dados_climaticos.extrai_dados scheduled__2022-09-26T00:00:00+00:00 [queued]>
[2022-12-28 18:52:32,240] {taskinstance.py:1159} INFO - Dependencies all met for <TaskInstance: dados_climaticos.extrai_dados scheduled__2022-09-26T00:00:00+00:00 [queued]>
[2022-12-28 18:52:32,240] {taskinstance.py:1356} INFO - 
--------------------------------------------------------------------------------
[2022-12-28 18:52:32,241] {taskinstance.py:1357} INFO - Starting attempt 1 of 1
[2022-12-28 18:52:32,241] {taskinstance.py:1358} INFO - 
--------------------------------------------------------------------------------
[2022-12-28 18:52:32,282] {taskinstance.py:1377} INFO - Executing <Task(PythonOperator): extrai_dados> on 2022-09-26 00:00:00+00:00
[2022-12-28 18:52:32,291] {standard_task_runner.py:52} INFO - Started process 21038 to run task
[2022-12-28 18:52:32,305] {standard_task_runner.py:79} INFO - Running: ['airflow', 'tasks', 'run', 'dados_climaticos', 'extrai_dados', 'scheduled__2022-09-26T00:00:00+00:00', '--job-id', '22', '--raw', '--subdir', 'DAGS_FOLDER/dados_climaticos.py', '--cfg-path', '/tmp/tmp153hg1pw', '--error-file', '/tmp/tmpibtrvgbf']
[2022-12-28 18:52:32,307] {standard_task_runner.py:80} INFO - Job 22: Subtask extrai_dados
[2022-12-28 18:52:32,465] {task_command.py:370} INFO - Running <TaskInstance: dados_climaticos.extrai_dados scheduled__2022-09-26T00:00:00+00:00 [running]> on host alxavier-airflow
[2022-12-28 18:52:32,581] {taskinstance.py:1569} INFO - Exporting the following env vars:
AIRFLOW_CTX_DAG_OWNER=airflow
AIRFLOW_CTX_DAG_ID=dados_climaticos
AIRFLOW_CTX_TASK_ID=extrai_dados
AIRFLOW_CTX_EXECUTION_DATE=2022-09-26T00:00:00+00:00
AIRFLOW_CTX_TRY_NUMBER=1
AIRFLOW_CTX_DAG_RUN_ID=scheduled__2022-09-26T00:00:00+00:00
[2022-12-28 18:52:33,468] {python.py:173} INFO - Done. Returned value was: None
[2022-12-28 18:52:33,479] {taskinstance.py:1395} INFO - Marking task as SUCCESS. dag_id=dados_climaticos, task_id=extrai_dados, execution_date=20220926T000000, start_date=20221228T215232, end_date=20221228T215233
[2022-12-28 18:52:33,532] {local_task_job.py:156} INFO - Task exited with return code 0
[2022-12-28 18:52:33,581] {local_task_job.py:273} INFO - 0 downstream tasks scheduled from follow-on schedule check
