[2022-12-28 18:29:43,840] {taskinstance.py:1159} INFO - Dependencies all met for <TaskInstance: dados_climaticos.extrai_dados scheduled__2022-10-31T00:00:00+00:00 [queued]>
[2022-12-28 18:29:43,896] {taskinstance.py:1159} INFO - Dependencies all met for <TaskInstance: dados_climaticos.extrai_dados scheduled__2022-10-31T00:00:00+00:00 [queued]>
[2022-12-28 18:29:43,896] {taskinstance.py:1356} INFO - 
--------------------------------------------------------------------------------
[2022-12-28 18:29:43,896] {taskinstance.py:1357} INFO - Starting attempt 1 of 1
[2022-12-28 18:29:43,897] {taskinstance.py:1358} INFO - 
--------------------------------------------------------------------------------
[2022-12-28 18:29:43,932] {taskinstance.py:1377} INFO - Executing <Task(PythonOperator): extrai_dados> on 2022-10-31 00:00:00+00:00
[2022-12-28 18:29:43,937] {standard_task_runner.py:52} INFO - Started process 18561 to run task
[2022-12-28 18:29:43,947] {standard_task_runner.py:79} INFO - Running: ['airflow', 'tasks', 'run', 'dados_climaticos', 'extrai_dados', 'scheduled__2022-10-31T00:00:00+00:00', '--job-id', '33', '--raw', '--subdir', 'DAGS_FOLDER/dados_climaticos.py', '--cfg-path', '/tmp/tmp7xr6vc68', '--error-file', '/tmp/tmpr926m_kf']
[2022-12-28 18:29:43,949] {standard_task_runner.py:80} INFO - Job 33: Subtask extrai_dados
[2022-12-28 18:29:44,133] {task_command.py:370} INFO - Running <TaskInstance: dados_climaticos.extrai_dados scheduled__2022-10-31T00:00:00+00:00 [running]> on host alxavier-airflow
[2022-12-28 18:29:44,182] {taskinstance.py:1889} ERROR - Task failed with exception
Traceback (most recent call last):
  File "/home/alxavier/Documents/airflowalura/venv/lib/python3.9/site-packages/airflow/models/taskinstance.py", line 1451, in _run_raw_task
    self._execute_task_with_callbacks(context, test_mode)
  File "/home/alxavier/Documents/airflowalura/venv/lib/python3.9/site-packages/airflow/models/taskinstance.py", line 1555, in _execute_task_with_callbacks
    task_orig = self.render_templates(context=context)
  File "/home/alxavier/Documents/airflowalura/venv/lib/python3.9/site-packages/airflow/models/taskinstance.py", line 2212, in render_templates
    rendered_task = self.task.render_template_fields(context)
  File "/home/alxavier/Documents/airflowalura/venv/lib/python3.9/site-packages/airflow/models/baseoperator.py", line 1185, in render_template_fields
    self._do_render_template_fields(self, self.template_fields, context, jinja_env, set())
  File "/home/alxavier/Documents/airflowalura/venv/lib/python3.9/site-packages/airflow/utils/session.py", line 71, in wrapper
    return func(*args, session=session, **kwargs)
  File "/home/alxavier/Documents/airflowalura/venv/lib/python3.9/site-packages/airflow/models/abstractoperator.py", line 344, in _do_render_template_fields
    rendered_content = self.render_template(
  File "/home/alxavier/Documents/airflowalura/venv/lib/python3.9/site-packages/airflow/models/abstractoperator.py", line 404, in render_template
    return {key: self.render_template(value, context, jinja_env) for key, value in value.items()}
  File "/home/alxavier/Documents/airflowalura/venv/lib/python3.9/site-packages/airflow/models/abstractoperator.py", line 404, in <dictcomp>
    return {key: self.render_template(value, context, jinja_env) for key, value in value.items()}
  File "/home/alxavier/Documents/airflowalura/venv/lib/python3.9/site-packages/airflow/models/abstractoperator.py", line 387, in render_template
    template = jinja_env.from_string(value)
  File "/home/alxavier/Documents/airflowalura/venv/lib/python3.9/site-packages/jinja2/environment.py", line 1092, in from_string
    return cls.from_code(self, self.compile(source), gs, None)
  File "/home/alxavier/Documents/airflowalura/venv/lib/python3.9/site-packages/jinja2/environment.py", line 757, in compile
    self.handle_exception(source=source_hint)
  File "/home/alxavier/Documents/airflowalura/venv/lib/python3.9/site-packages/jinja2/environment.py", line 925, in handle_exception
    raise rewrite_traceback_stack(source=source)
  File "<unknown>", line 1, in template
jinja2.exceptions.TemplateSyntaxError: unexpected char '"' at 29
[2022-12-28 18:29:44,193] {taskinstance.py:1395} INFO - Marking task as FAILED. dag_id=dados_climaticos, task_id=extrai_dados, execution_date=20221031T000000, start_date=20221228T212943, end_date=20221228T212944
[2022-12-28 18:29:44,226] {standard_task_runner.py:92} ERROR - Failed to execute job 33 for task extrai_dados (unexpected char '"' at 29; 18561)
[2022-12-28 18:29:44,244] {local_task_job.py:156} INFO - Task exited with return code 1
[2022-12-28 18:29:44,290] {local_task_job.py:273} INFO - 0 downstream tasks scheduled from follow-on schedule check
[2022-12-28 18:46:11,800] {taskinstance.py:1159} INFO - Dependencies all met for <TaskInstance: dados_climaticos.extrai_dados scheduled__2022-10-31T00:00:00+00:00 [queued]>
[2022-12-28 18:46:11,834] {taskinstance.py:1159} INFO - Dependencies all met for <TaskInstance: dados_climaticos.extrai_dados scheduled__2022-10-31T00:00:00+00:00 [queued]>
[2022-12-28 18:46:11,834] {taskinstance.py:1356} INFO - 
--------------------------------------------------------------------------------
[2022-12-28 18:46:11,834] {taskinstance.py:1357} INFO - Starting attempt 1 of 1
[2022-12-28 18:46:11,835] {taskinstance.py:1358} INFO - 
--------------------------------------------------------------------------------
[2022-12-28 18:46:11,893] {taskinstance.py:1377} INFO - Executing <Task(PythonOperator): extrai_dados> on 2022-10-31 00:00:00+00:00
[2022-12-28 18:46:11,901] {standard_task_runner.py:52} INFO - Started process 20328 to run task
[2022-12-28 18:46:11,916] {standard_task_runner.py:79} INFO - Running: ['airflow', 'tasks', 'run', 'dados_climaticos', 'extrai_dados', 'scheduled__2022-10-31T00:00:00+00:00', '--job-id', '33', '--raw', '--subdir', 'DAGS_FOLDER/dados_climaticos.py', '--cfg-path', '/tmp/tmpv4oolhwf', '--error-file', '/tmp/tmpqlo6py9u']
[2022-12-28 18:46:11,917] {standard_task_runner.py:80} INFO - Job 33: Subtask extrai_dados
[2022-12-28 18:46:12,172] {task_command.py:370} INFO - Running <TaskInstance: dados_climaticos.extrai_dados scheduled__2022-10-31T00:00:00+00:00 [running]> on host alxavier-airflow
[2022-12-28 18:46:12,313] {taskinstance.py:1569} INFO - Exporting the following env vars:
AIRFLOW_CTX_DAG_OWNER=airflow
AIRFLOW_CTX_DAG_ID=dados_climaticos
AIRFLOW_CTX_TASK_ID=extrai_dados
AIRFLOW_CTX_EXECUTION_DATE=2022-10-31T00:00:00+00:00
AIRFLOW_CTX_TRY_NUMBER=1
AIRFLOW_CTX_DAG_RUN_ID=scheduled__2022-10-31T00:00:00+00:00
[2022-12-28 18:46:13,480] {taskinstance.py:1889} ERROR - Task failed with exception
Traceback (most recent call last):
  File "/home/alxavier/Documents/airflowalura/venv/lib/python3.9/site-packages/airflow/operators/python.py", line 171, in execute
    return_value = self.execute_callable()
  File "/home/alxavier/Documents/airflowalura/venv/lib/python3.9/site-packages/airflow/operators/python.py", line 189, in execute_callable
    return self.python_callable(*self.op_args, **self.op_kwargs)
  File "/home/alxavier/Documents/airflowalura/dags/dados_climaticos.py", line 33, in extrai_dados
    dados.to_csv(file_path + 'dados_brutos.csv')
  File "/home/alxavier/Documents/airflowalura/venv/lib/python3.9/site-packages/pandas/util/_decorators.py", line 211, in wrapper
    return func(*args, **kwargs)
  File "/home/alxavier/Documents/airflowalura/venv/lib/python3.9/site-packages/pandas/core/generic.py", line 3720, in to_csv
    return DataFrameRenderer(formatter).to_csv(
  File "/home/alxavier/Documents/airflowalura/venv/lib/python3.9/site-packages/pandas/util/_decorators.py", line 211, in wrapper
    return func(*args, **kwargs)
  File "/home/alxavier/Documents/airflowalura/venv/lib/python3.9/site-packages/pandas/io/formats/format.py", line 1189, in to_csv
    csv_formatter.save()
  File "/home/alxavier/Documents/airflowalura/venv/lib/python3.9/site-packages/pandas/io/formats/csvs.py", line 241, in save
    with get_handle(
  File "/home/alxavier/Documents/airflowalura/venv/lib/python3.9/site-packages/pandas/io/common.py", line 734, in get_handle
    check_parent_directory(str(handle))
  File "/home/alxavier/Documents/airflowalura/venv/lib/python3.9/site-packages/pandas/io/common.py", line 597, in check_parent_directory
    raise OSError(rf"Cannot save file into a non-existent directory: '{parent}'")
OSError: Cannot save file into a non-existent directory: '/home/alxavier/Documents/airflowalura/semana={data_interval_end}'
[2022-12-28 18:46:13,492] {taskinstance.py:1395} INFO - Marking task as FAILED. dag_id=dados_climaticos, task_id=extrai_dados, execution_date=20221031T000000, start_date=20221228T214611, end_date=20221228T214613
[2022-12-28 18:46:13,557] {standard_task_runner.py:92} ERROR - Failed to execute job 33 for task extrai_dados (Cannot save file into a non-existent directory: '/home/alxavier/Documents/airflowalura/semana={data_interval_end}'; 20328)
[2022-12-28 18:46:13,571] {local_task_job.py:156} INFO - Task exited with return code 1
[2022-12-28 18:46:13,643] {local_task_job.py:273} INFO - 0 downstream tasks scheduled from follow-on schedule check
[2022-12-28 18:53:25,978] {taskinstance.py:1159} INFO - Dependencies all met for <TaskInstance: dados_climaticos.extrai_dados scheduled__2022-10-31T00:00:00+00:00 [queued]>
[2022-12-28 18:53:25,993] {taskinstance.py:1159} INFO - Dependencies all met for <TaskInstance: dados_climaticos.extrai_dados scheduled__2022-10-31T00:00:00+00:00 [queued]>
[2022-12-28 18:53:25,994] {taskinstance.py:1356} INFO - 
--------------------------------------------------------------------------------
[2022-12-28 18:53:25,994] {taskinstance.py:1357} INFO - Starting attempt 1 of 1
[2022-12-28 18:53:25,994] {taskinstance.py:1358} INFO - 
--------------------------------------------------------------------------------
[2022-12-28 18:53:26,036] {taskinstance.py:1377} INFO - Executing <Task(PythonOperator): extrai_dados> on 2022-10-31 00:00:00+00:00
[2022-12-28 18:53:26,044] {standard_task_runner.py:52} INFO - Started process 21148 to run task
[2022-12-28 18:53:26,089] {standard_task_runner.py:79} INFO - Running: ['airflow', 'tasks', 'run', 'dados_climaticos', 'extrai_dados', 'scheduled__2022-10-31T00:00:00+00:00', '--job-id', '33', '--raw', '--subdir', 'DAGS_FOLDER/dados_climaticos.py', '--cfg-path', '/tmp/tmpxsyh_7vr', '--error-file', '/tmp/tmpaoenuqmh']
[2022-12-28 18:53:26,118] {standard_task_runner.py:80} INFO - Job 33: Subtask extrai_dados
[2022-12-28 18:53:26,263] {task_command.py:370} INFO - Running <TaskInstance: dados_climaticos.extrai_dados scheduled__2022-10-31T00:00:00+00:00 [running]> on host alxavier-airflow
[2022-12-28 18:53:26,387] {taskinstance.py:1569} INFO - Exporting the following env vars:
AIRFLOW_CTX_DAG_OWNER=airflow
AIRFLOW_CTX_DAG_ID=dados_climaticos
AIRFLOW_CTX_TASK_ID=extrai_dados
AIRFLOW_CTX_EXECUTION_DATE=2022-10-31T00:00:00+00:00
AIRFLOW_CTX_TRY_NUMBER=1
AIRFLOW_CTX_DAG_RUN_ID=scheduled__2022-10-31T00:00:00+00:00
[2022-12-28 18:53:28,675] {python.py:173} INFO - Done. Returned value was: None
[2022-12-28 18:53:28,695] {taskinstance.py:1395} INFO - Marking task as SUCCESS. dag_id=dados_climaticos, task_id=extrai_dados, execution_date=20221031T000000, start_date=20221228T215325, end_date=20221228T215328
[2022-12-28 18:53:28,793] {local_task_job.py:156} INFO - Task exited with return code 0
[2022-12-28 18:53:28,826] {local_task_job.py:273} INFO - 0 downstream tasks scheduled from follow-on schedule check
