[2022-12-28 18:29:55,733] {taskinstance.py:1159} INFO - Dependencies all met for <TaskInstance: dados_climaticos.extrai_dados scheduled__2022-11-14T00:00:00+00:00 [queued]>
[2022-12-28 18:29:55,747] {taskinstance.py:1159} INFO - Dependencies all met for <TaskInstance: dados_climaticos.extrai_dados scheduled__2022-11-14T00:00:00+00:00 [queued]>
[2022-12-28 18:29:55,748] {taskinstance.py:1356} INFO - 
--------------------------------------------------------------------------------
[2022-12-28 18:29:55,748] {taskinstance.py:1357} INFO - Starting attempt 1 of 1
[2022-12-28 18:29:55,748] {taskinstance.py:1358} INFO - 
--------------------------------------------------------------------------------
[2022-12-28 18:29:55,789] {taskinstance.py:1377} INFO - Executing <Task(PythonOperator): extrai_dados> on 2022-11-14 00:00:00+00:00
[2022-12-28 18:29:55,795] {standard_task_runner.py:52} INFO - Started process 18585 to run task
[2022-12-28 18:29:55,801] {standard_task_runner.py:79} INFO - Running: ['airflow', 'tasks', 'run', 'dados_climaticos', 'extrai_dados', 'scheduled__2022-11-14T00:00:00+00:00', '--job-id', '36', '--raw', '--subdir', 'DAGS_FOLDER/dados_climaticos.py', '--cfg-path', '/tmp/tmp0l6m81qw', '--error-file', '/tmp/tmp5yuswbwo']
[2022-12-28 18:29:55,802] {standard_task_runner.py:80} INFO - Job 36: Subtask extrai_dados
[2022-12-28 18:29:55,961] {task_command.py:370} INFO - Running <TaskInstance: dados_climaticos.extrai_dados scheduled__2022-11-14T00:00:00+00:00 [running]> on host alxavier-airflow
[2022-12-28 18:29:56,011] {taskinstance.py:1889} ERROR - Task failed with exception
Traceback (most recent call last):
  File "/home/alxavier/Documents/airflowalura/venv/lib/python3.9/site-packages/airflow/models/taskinstance.py", line 1451, in _run_raw_task
    self._execute_task_with_callbacks(context, test_mode)
  File "/home/alxavier/Documents/airflowalura/venv/lib/python3.9/site-packages/airflow/models/taskinstance.py", line 1555, in _execute_task_with_callbacks
    task_orig = self.render_templates(context=context)
  File "/home/alxavier/Documents/airflowalura/venv/lib/python3.9/site-packages/airflow/models/taskinstance.py", line 2212, in render_templates
    rendered_task = self.task.render_template_fields(context)
  File "/home/alxavier/Documents/airflowalura/venv/lib/python3.9/site-packages/airflow/models/baseoperator.py", line 1185, in render_template_fields
    self._do_render_template_fields(self, self.template_fields, context, jinja_env, set())
  File "/home/alxavier/Documents/airflowalura/venv/lib/python3.9/site-packages/airflow/utils/session.py", line 71, in wrapper
    return func(*args, session=session, **kwargs)
  File "/home/alxavier/Documents/airflowalura/venv/lib/python3.9/site-packages/airflow/models/abstractoperator.py", line 344, in _do_render_template_fields
    rendered_content = self.render_template(
  File "/home/alxavier/Documents/airflowalura/venv/lib/python3.9/site-packages/airflow/models/abstractoperator.py", line 404, in render_template
    return {key: self.render_template(value, context, jinja_env) for key, value in value.items()}
  File "/home/alxavier/Documents/airflowalura/venv/lib/python3.9/site-packages/airflow/models/abstractoperator.py", line 404, in <dictcomp>
    return {key: self.render_template(value, context, jinja_env) for key, value in value.items()}
  File "/home/alxavier/Documents/airflowalura/venv/lib/python3.9/site-packages/airflow/models/abstractoperator.py", line 387, in render_template
    template = jinja_env.from_string(value)
  File "/home/alxavier/Documents/airflowalura/venv/lib/python3.9/site-packages/jinja2/environment.py", line 1092, in from_string
    return cls.from_code(self, self.compile(source), gs, None)
  File "/home/alxavier/Documents/airflowalura/venv/lib/python3.9/site-packages/jinja2/environment.py", line 757, in compile
    self.handle_exception(source=source_hint)
  File "/home/alxavier/Documents/airflowalura/venv/lib/python3.9/site-packages/jinja2/environment.py", line 925, in handle_exception
    raise rewrite_traceback_stack(source=source)
  File "<unknown>", line 1, in template
jinja2.exceptions.TemplateSyntaxError: unexpected char '"' at 29
[2022-12-28 18:29:56,026] {taskinstance.py:1395} INFO - Marking task as FAILED. dag_id=dados_climaticos, task_id=extrai_dados, execution_date=20221114T000000, start_date=20221228T212955, end_date=20221228T212956
[2022-12-28 18:29:56,062] {standard_task_runner.py:92} ERROR - Failed to execute job 36 for task extrai_dados (unexpected char '"' at 29; 18585)
[2022-12-28 18:29:56,088] {local_task_job.py:156} INFO - Task exited with return code 1
[2022-12-28 18:29:56,120] {local_task_job.py:273} INFO - 0 downstream tasks scheduled from follow-on schedule check
[2022-12-28 18:46:37,006] {taskinstance.py:1159} INFO - Dependencies all met for <TaskInstance: dados_climaticos.extrai_dados scheduled__2022-11-14T00:00:00+00:00 [queued]>
[2022-12-28 18:46:37,020] {taskinstance.py:1159} INFO - Dependencies all met for <TaskInstance: dados_climaticos.extrai_dados scheduled__2022-11-14T00:00:00+00:00 [queued]>
[2022-12-28 18:46:37,021] {taskinstance.py:1356} INFO - 
--------------------------------------------------------------------------------
[2022-12-28 18:46:37,022] {taskinstance.py:1357} INFO - Starting attempt 1 of 1
[2022-12-28 18:46:37,023] {taskinstance.py:1358} INFO - 
--------------------------------------------------------------------------------
[2022-12-28 18:46:37,084] {taskinstance.py:1377} INFO - Executing <Task(PythonOperator): extrai_dados> on 2022-11-14 00:00:00+00:00
[2022-12-28 18:46:37,092] {standard_task_runner.py:52} INFO - Started process 20368 to run task
[2022-12-28 18:46:37,102] {standard_task_runner.py:79} INFO - Running: ['airflow', 'tasks', 'run', 'dados_climaticos', 'extrai_dados', 'scheduled__2022-11-14T00:00:00+00:00', '--job-id', '37', '--raw', '--subdir', 'DAGS_FOLDER/dados_climaticos.py', '--cfg-path', '/tmp/tmpww5bmiht', '--error-file', '/tmp/tmplgwmryoe']
[2022-12-28 18:46:37,104] {standard_task_runner.py:80} INFO - Job 37: Subtask extrai_dados
[2022-12-28 18:46:37,241] {task_command.py:370} INFO - Running <TaskInstance: dados_climaticos.extrai_dados scheduled__2022-11-14T00:00:00+00:00 [running]> on host alxavier-airflow
[2022-12-28 18:46:37,381] {taskinstance.py:1569} INFO - Exporting the following env vars:
AIRFLOW_CTX_DAG_OWNER=airflow
AIRFLOW_CTX_DAG_ID=dados_climaticos
AIRFLOW_CTX_TASK_ID=extrai_dados
AIRFLOW_CTX_EXECUTION_DATE=2022-11-14T00:00:00+00:00
AIRFLOW_CTX_TRY_NUMBER=1
AIRFLOW_CTX_DAG_RUN_ID=scheduled__2022-11-14T00:00:00+00:00
[2022-12-28 18:46:38,665] {taskinstance.py:1889} ERROR - Task failed with exception
Traceback (most recent call last):
  File "/home/alxavier/Documents/airflowalura/venv/lib/python3.9/site-packages/airflow/operators/python.py", line 171, in execute
    return_value = self.execute_callable()
  File "/home/alxavier/Documents/airflowalura/venv/lib/python3.9/site-packages/airflow/operators/python.py", line 189, in execute_callable
    return self.python_callable(*self.op_args, **self.op_kwargs)
  File "/home/alxavier/Documents/airflowalura/dags/dados_climaticos.py", line 33, in extrai_dados
    dados.to_csv(file_path + 'dados_brutos.csv')
  File "/home/alxavier/Documents/airflowalura/venv/lib/python3.9/site-packages/pandas/util/_decorators.py", line 211, in wrapper
    return func(*args, **kwargs)
  File "/home/alxavier/Documents/airflowalura/venv/lib/python3.9/site-packages/pandas/core/generic.py", line 3720, in to_csv
    return DataFrameRenderer(formatter).to_csv(
  File "/home/alxavier/Documents/airflowalura/venv/lib/python3.9/site-packages/pandas/util/_decorators.py", line 211, in wrapper
    return func(*args, **kwargs)
  File "/home/alxavier/Documents/airflowalura/venv/lib/python3.9/site-packages/pandas/io/formats/format.py", line 1189, in to_csv
    csv_formatter.save()
  File "/home/alxavier/Documents/airflowalura/venv/lib/python3.9/site-packages/pandas/io/formats/csvs.py", line 241, in save
    with get_handle(
  File "/home/alxavier/Documents/airflowalura/venv/lib/python3.9/site-packages/pandas/io/common.py", line 734, in get_handle
    check_parent_directory(str(handle))
  File "/home/alxavier/Documents/airflowalura/venv/lib/python3.9/site-packages/pandas/io/common.py", line 597, in check_parent_directory
    raise OSError(rf"Cannot save file into a non-existent directory: '{parent}'")
OSError: Cannot save file into a non-existent directory: '/home/alxavier/Documents/airflowalura/semana={data_interval_end}'
[2022-12-28 18:46:38,690] {taskinstance.py:1395} INFO - Marking task as FAILED. dag_id=dados_climaticos, task_id=extrai_dados, execution_date=20221114T000000, start_date=20221228T214637, end_date=20221228T214638
[2022-12-28 18:46:38,746] {standard_task_runner.py:92} ERROR - Failed to execute job 37 for task extrai_dados (Cannot save file into a non-existent directory: '/home/alxavier/Documents/airflowalura/semana={data_interval_end}'; 20368)
[2022-12-28 18:46:38,776] {local_task_job.py:156} INFO - Task exited with return code 1
[2022-12-28 18:46:38,855] {local_task_job.py:273} INFO - 0 downstream tasks scheduled from follow-on schedule check
[2022-12-28 18:53:56,592] {taskinstance.py:1159} INFO - Dependencies all met for <TaskInstance: dados_climaticos.extrai_dados scheduled__2022-11-14T00:00:00+00:00 [queued]>
[2022-12-28 18:53:56,606] {taskinstance.py:1159} INFO - Dependencies all met for <TaskInstance: dados_climaticos.extrai_dados scheduled__2022-11-14T00:00:00+00:00 [queued]>
[2022-12-28 18:53:56,607] {taskinstance.py:1356} INFO - 
--------------------------------------------------------------------------------
[2022-12-28 18:53:56,607] {taskinstance.py:1357} INFO - Starting attempt 1 of 1
[2022-12-28 18:53:56,607] {taskinstance.py:1358} INFO - 
--------------------------------------------------------------------------------
[2022-12-28 18:53:56,644] {taskinstance.py:1377} INFO - Executing <Task(PythonOperator): extrai_dados> on 2022-11-14 00:00:00+00:00
[2022-12-28 18:53:56,653] {standard_task_runner.py:52} INFO - Started process 21200 to run task
[2022-12-28 18:53:56,673] {standard_task_runner.py:79} INFO - Running: ['airflow', 'tasks', 'run', 'dados_climaticos', 'extrai_dados', 'scheduled__2022-11-14T00:00:00+00:00', '--job-id', '37', '--raw', '--subdir', 'DAGS_FOLDER/dados_climaticos.py', '--cfg-path', '/tmp/tmp7rcr_7ka', '--error-file', '/tmp/tmp5vcau0a7']
[2022-12-28 18:53:56,675] {standard_task_runner.py:80} INFO - Job 37: Subtask extrai_dados
[2022-12-28 18:53:56,842] {task_command.py:370} INFO - Running <TaskInstance: dados_climaticos.extrai_dados scheduled__2022-11-14T00:00:00+00:00 [running]> on host alxavier-airflow
[2022-12-28 18:53:56,975] {taskinstance.py:1569} INFO - Exporting the following env vars:
AIRFLOW_CTX_DAG_OWNER=airflow
AIRFLOW_CTX_DAG_ID=dados_climaticos
AIRFLOW_CTX_TASK_ID=extrai_dados
AIRFLOW_CTX_EXECUTION_DATE=2022-11-14T00:00:00+00:00
AIRFLOW_CTX_TRY_NUMBER=1
AIRFLOW_CTX_DAG_RUN_ID=scheduled__2022-11-14T00:00:00+00:00
[2022-12-28 18:53:57,968] {python.py:173} INFO - Done. Returned value was: None
[2022-12-28 18:53:58,001] {taskinstance.py:1395} INFO - Marking task as SUCCESS. dag_id=dados_climaticos, task_id=extrai_dados, execution_date=20221114T000000, start_date=20221228T215356, end_date=20221228T215358
[2022-12-28 18:53:58,103] {local_task_job.py:156} INFO - Task exited with return code 0
[2022-12-28 18:53:58,179] {local_task_job.py:273} INFO - 0 downstream tasks scheduled from follow-on schedule check
