[2022-12-28 17:50:35,648] {taskinstance.py:1159} INFO - Dependencies all met for <TaskInstance: dados_climaticos.cria_pasta scheduled__2022-12-12T00:00:00+00:00 [queued]>
[2022-12-28 17:50:35,663] {taskinstance.py:1159} INFO - Dependencies all met for <TaskInstance: dados_climaticos.cria_pasta scheduled__2022-12-12T00:00:00+00:00 [queued]>
[2022-12-28 17:50:35,663] {taskinstance.py:1356} INFO - 
--------------------------------------------------------------------------------
[2022-12-28 17:50:35,664] {taskinstance.py:1357} INFO - Starting attempt 1 of 1
[2022-12-28 17:50:35,673] {taskinstance.py:1358} INFO - 
--------------------------------------------------------------------------------
[2022-12-28 17:50:35,758] {taskinstance.py:1377} INFO - Executing <Task(BashOperator): cria_pasta> on 2022-12-12 00:00:00+00:00
[2022-12-28 17:50:35,764] {standard_task_runner.py:52} INFO - Started process 14332 to run task
[2022-12-28 17:50:35,780] {standard_task_runner.py:79} INFO - Running: ['airflow', 'tasks', 'run', 'dados_climaticos', 'cria_pasta', 'scheduled__2022-12-12T00:00:00+00:00', '--job-id', '27', '--raw', '--subdir', 'DAGS_FOLDER/dados_climaticos.py', '--cfg-path', '/tmp/tmp5g97_duc', '--error-file', '/tmp/tmpqmzqol70']
[2022-12-28 17:50:35,782] {standard_task_runner.py:80} INFO - Job 27: Subtask cria_pasta
[2022-12-28 17:50:35,915] {task_command.py:370} INFO - Running <TaskInstance: dados_climaticos.cria_pasta scheduled__2022-12-12T00:00:00+00:00 [running]> on host alxavier-airflow
[2022-12-28 17:50:35,996] {taskinstance.py:1889} ERROR - Task failed with exception
Traceback (most recent call last):
  File "/home/alxavier/Documents/airflowalura/venv/lib/python3.9/site-packages/airflow/models/taskinstance.py", line 1451, in _run_raw_task
    self._execute_task_with_callbacks(context, test_mode)
  File "/home/alxavier/Documents/airflowalura/venv/lib/python3.9/site-packages/airflow/models/taskinstance.py", line 1555, in _execute_task_with_callbacks
    task_orig = self.render_templates(context=context)
  File "/home/alxavier/Documents/airflowalura/venv/lib/python3.9/site-packages/airflow/models/taskinstance.py", line 2212, in render_templates
    rendered_task = self.task.render_template_fields(context)
  File "/home/alxavier/Documents/airflowalura/venv/lib/python3.9/site-packages/airflow/models/baseoperator.py", line 1185, in render_template_fields
    self._do_render_template_fields(self, self.template_fields, context, jinja_env, set())
  File "/home/alxavier/Documents/airflowalura/venv/lib/python3.9/site-packages/airflow/utils/session.py", line 71, in wrapper
    return func(*args, session=session, **kwargs)
  File "/home/alxavier/Documents/airflowalura/venv/lib/python3.9/site-packages/airflow/models/abstractoperator.py", line 344, in _do_render_template_fields
    rendered_content = self.render_template(
  File "/home/alxavier/Documents/airflowalura/venv/lib/python3.9/site-packages/airflow/models/abstractoperator.py", line 387, in render_template
    template = jinja_env.from_string(value)
  File "/home/alxavier/Documents/airflowalura/venv/lib/python3.9/site-packages/jinja2/environment.py", line 1092, in from_string
    return cls.from_code(self, self.compile(source), gs, None)
  File "/home/alxavier/Documents/airflowalura/venv/lib/python3.9/site-packages/jinja2/environment.py", line 757, in compile
    self.handle_exception(source=source_hint)
  File "/home/alxavier/Documents/airflowalura/venv/lib/python3.9/site-packages/jinja2/environment.py", line 925, in handle_exception
    raise rewrite_traceback_stack(source=source)
  File "<unknown>", line 1, in template
jinja2.exceptions.TemplateSyntaxError: unexpected end of template, expected ','.
[2022-12-28 17:50:36,006] {taskinstance.py:1395} INFO - Marking task as FAILED. dag_id=dados_climaticos, task_id=cria_pasta, execution_date=20221212T000000, start_date=20221228T205035, end_date=20221228T205036
[2022-12-28 17:50:36,041] {standard_task_runner.py:92} ERROR - Failed to execute job 27 for task cria_pasta (unexpected end of template, expected ','.; 14332)
[2022-12-28 17:50:36,085] {local_task_job.py:156} INFO - Task exited with return code 1
[2022-12-28 17:50:36,193] {local_task_job.py:273} INFO - 0 downstream tasks scheduled from follow-on schedule check
[2022-12-28 18:15:02,954] {taskinstance.py:1159} INFO - Dependencies all met for <TaskInstance: dados_climaticos.cria_pasta scheduled__2022-12-12T00:00:00+00:00 [queued]>
[2022-12-28 18:15:02,963] {taskinstance.py:1159} INFO - Dependencies all met for <TaskInstance: dados_climaticos.cria_pasta scheduled__2022-12-12T00:00:00+00:00 [queued]>
[2022-12-28 18:15:02,963] {taskinstance.py:1356} INFO - 
--------------------------------------------------------------------------------
[2022-12-28 18:15:02,963] {taskinstance.py:1357} INFO - Starting attempt 1 of 1
[2022-12-28 18:15:02,963] {taskinstance.py:1358} INFO - 
--------------------------------------------------------------------------------
[2022-12-28 18:15:02,989] {taskinstance.py:1377} INFO - Executing <Task(BashOperator): cria_pasta> on 2022-12-12 00:00:00+00:00
[2022-12-28 18:15:02,995] {standard_task_runner.py:52} INFO - Started process 16948 to run task
[2022-12-28 18:15:03,002] {standard_task_runner.py:79} INFO - Running: ['airflow', 'tasks', 'run', 'dados_climaticos', 'cria_pasta', 'scheduled__2022-12-12T00:00:00+00:00', '--job-id', '27', '--raw', '--subdir', 'DAGS_FOLDER/dados_climaticos.py', '--cfg-path', '/tmp/tmpsnrc4u9b', '--error-file', '/tmp/tmpfmp8x3t_']
[2022-12-28 18:15:03,003] {standard_task_runner.py:80} INFO - Job 27: Subtask cria_pasta
[2022-12-28 18:15:03,108] {task_command.py:370} INFO - Running <TaskInstance: dados_climaticos.cria_pasta scheduled__2022-12-12T00:00:00+00:00 [running]> on host alxavier-airflow
[2022-12-28 18:15:03,161] {taskinstance.py:1889} ERROR - Task failed with exception
Traceback (most recent call last):
  File "/home/alxavier/Documents/airflowalura/venv/lib/python3.9/site-packages/airflow/models/taskinstance.py", line 1451, in _run_raw_task
    self._execute_task_with_callbacks(context, test_mode)
  File "/home/alxavier/Documents/airflowalura/venv/lib/python3.9/site-packages/airflow/models/taskinstance.py", line 1555, in _execute_task_with_callbacks
    task_orig = self.render_templates(context=context)
  File "/home/alxavier/Documents/airflowalura/venv/lib/python3.9/site-packages/airflow/models/taskinstance.py", line 2212, in render_templates
    rendered_task = self.task.render_template_fields(context)
  File "/home/alxavier/Documents/airflowalura/venv/lib/python3.9/site-packages/airflow/models/baseoperator.py", line 1185, in render_template_fields
    self._do_render_template_fields(self, self.template_fields, context, jinja_env, set())
  File "/home/alxavier/Documents/airflowalura/venv/lib/python3.9/site-packages/airflow/utils/session.py", line 71, in wrapper
    return func(*args, session=session, **kwargs)
  File "/home/alxavier/Documents/airflowalura/venv/lib/python3.9/site-packages/airflow/models/abstractoperator.py", line 344, in _do_render_template_fields
    rendered_content = self.render_template(
  File "/home/alxavier/Documents/airflowalura/venv/lib/python3.9/site-packages/airflow/models/abstractoperator.py", line 387, in render_template
    template = jinja_env.from_string(value)
  File "/home/alxavier/Documents/airflowalura/venv/lib/python3.9/site-packages/jinja2/environment.py", line 1092, in from_string
    return cls.from_code(self, self.compile(source), gs, None)
  File "/home/alxavier/Documents/airflowalura/venv/lib/python3.9/site-packages/jinja2/environment.py", line 757, in compile
    self.handle_exception(source=source_hint)
  File "/home/alxavier/Documents/airflowalura/venv/lib/python3.9/site-packages/jinja2/environment.py", line 925, in handle_exception
    raise rewrite_traceback_stack(source=source)
  File "<unknown>", line 1, in template
jinja2.exceptions.TemplateSyntaxError: unexpected end of template, expected ','.
[2022-12-28 18:15:03,171] {taskinstance.py:1395} INFO - Marking task as FAILED. dag_id=dados_climaticos, task_id=cria_pasta, execution_date=20221212T000000, start_date=20221228T211502, end_date=20221228T211503
[2022-12-28 18:15:03,197] {standard_task_runner.py:92} ERROR - Failed to execute job 27 for task cria_pasta (unexpected end of template, expected ','.; 16948)
[2022-12-28 18:15:03,231] {local_task_job.py:156} INFO - Task exited with return code 1
[2022-12-28 18:15:03,326] {local_task_job.py:273} INFO - 0 downstream tasks scheduled from follow-on schedule check
[2022-12-28 18:30:34,094] {taskinstance.py:1159} INFO - Dependencies all met for <TaskInstance: dados_climaticos.cria_pasta scheduled__2022-12-12T00:00:00+00:00 [queued]>
[2022-12-28 18:30:34,108] {taskinstance.py:1159} INFO - Dependencies all met for <TaskInstance: dados_climaticos.cria_pasta scheduled__2022-12-12T00:00:00+00:00 [queued]>
[2022-12-28 18:30:34,109] {taskinstance.py:1356} INFO - 
--------------------------------------------------------------------------------
[2022-12-28 18:30:34,109] {taskinstance.py:1357} INFO - Starting attempt 1 of 1
[2022-12-28 18:30:34,109] {taskinstance.py:1358} INFO - 
--------------------------------------------------------------------------------
[2022-12-28 18:30:34,145] {taskinstance.py:1377} INFO - Executing <Task(BashOperator): cria_pasta> on 2022-12-12 00:00:00+00:00
[2022-12-28 18:30:34,153] {standard_task_runner.py:52} INFO - Started process 18657 to run task
[2022-12-28 18:30:34,168] {standard_task_runner.py:79} INFO - Running: ['airflow', 'tasks', 'run', 'dados_climaticos', 'cria_pasta', 'scheduled__2022-12-12T00:00:00+00:00', '--job-id', '43', '--raw', '--subdir', 'DAGS_FOLDER/dados_climaticos.py', '--cfg-path', '/tmp/tmp9cal5wiy', '--error-file', '/tmp/tmp6k9qmndv']
[2022-12-28 18:30:34,169] {standard_task_runner.py:80} INFO - Job 43: Subtask cria_pasta
[2022-12-28 18:30:34,346] {task_command.py:370} INFO - Running <TaskInstance: dados_climaticos.cria_pasta scheduled__2022-12-12T00:00:00+00:00 [running]> on host alxavier-airflow
[2022-12-28 18:30:34,500] {taskinstance.py:1569} INFO - Exporting the following env vars:
AIRFLOW_CTX_DAG_OWNER=airflow
AIRFLOW_CTX_DAG_ID=dados_climaticos
AIRFLOW_CTX_TASK_ID=cria_pasta
AIRFLOW_CTX_EXECUTION_DATE=2022-12-12T00:00:00+00:00
AIRFLOW_CTX_TRY_NUMBER=1
AIRFLOW_CTX_DAG_RUN_ID=scheduled__2022-12-12T00:00:00+00:00
[2022-12-28 18:30:34,502] {subprocess.py:62} INFO - Tmp dir root location: 
 /tmp
[2022-12-28 18:30:34,504] {subprocess.py:74} INFO - Running command: ['bash', '-c', 'mkdir -p "/home/alxavier/Documents/airflowalura/semana=2022-12-19"']
[2022-12-28 18:30:34,517] {subprocess.py:85} INFO - Output:
[2022-12-28 18:30:34,529] {subprocess.py:96} INFO - Command exited with return code 0
[2022-12-28 18:30:34,582] {taskinstance.py:1395} INFO - Marking task as SUCCESS. dag_id=dados_climaticos, task_id=cria_pasta, execution_date=20221212T000000, start_date=20221228T213034, end_date=20221228T213034
[2022-12-28 18:30:34,672] {local_task_job.py:156} INFO - Task exited with return code 0
[2022-12-28 18:30:34,785] {local_task_job.py:273} INFO - 1 downstream tasks scheduled from follow-on schedule check
[2022-12-28 18:54:25,851] {taskinstance.py:1159} INFO - Dependencies all met for <TaskInstance: dados_climaticos.cria_pasta scheduled__2022-12-12T00:00:00+00:00 [queued]>
[2022-12-28 18:54:25,860] {taskinstance.py:1159} INFO - Dependencies all met for <TaskInstance: dados_climaticos.cria_pasta scheduled__2022-12-12T00:00:00+00:00 [queued]>
[2022-12-28 18:54:25,860] {taskinstance.py:1356} INFO - 
--------------------------------------------------------------------------------
[2022-12-28 18:54:25,860] {taskinstance.py:1357} INFO - Starting attempt 1 of 1
[2022-12-28 18:54:25,861] {taskinstance.py:1358} INFO - 
--------------------------------------------------------------------------------
[2022-12-28 18:54:25,905] {taskinstance.py:1377} INFO - Executing <Task(BashOperator): cria_pasta> on 2022-12-12 00:00:00+00:00
[2022-12-28 18:54:25,911] {standard_task_runner.py:52} INFO - Started process 21255 to run task
[2022-12-28 18:54:25,927] {standard_task_runner.py:79} INFO - Running: ['airflow', 'tasks', 'run', 'dados_climaticos', 'cria_pasta', 'scheduled__2022-12-12T00:00:00+00:00', '--job-id', '42', '--raw', '--subdir', 'DAGS_FOLDER/dados_climaticos.py', '--cfg-path', '/tmp/tmpcev476ni', '--error-file', '/tmp/tmphhx7_zzl']
[2022-12-28 18:54:25,932] {standard_task_runner.py:80} INFO - Job 42: Subtask cria_pasta
[2022-12-28 18:54:26,040] {task_command.py:370} INFO - Running <TaskInstance: dados_climaticos.cria_pasta scheduled__2022-12-12T00:00:00+00:00 [running]> on host alxavier-airflow
[2022-12-28 18:54:26,260] {taskinstance.py:1569} INFO - Exporting the following env vars:
AIRFLOW_CTX_DAG_OWNER=airflow
AIRFLOW_CTX_DAG_ID=dados_climaticos
AIRFLOW_CTX_TASK_ID=cria_pasta
AIRFLOW_CTX_EXECUTION_DATE=2022-12-12T00:00:00+00:00
AIRFLOW_CTX_TRY_NUMBER=1
AIRFLOW_CTX_DAG_RUN_ID=scheduled__2022-12-12T00:00:00+00:00
[2022-12-28 18:54:26,262] {subprocess.py:62} INFO - Tmp dir root location: 
 /tmp
[2022-12-28 18:54:26,263] {subprocess.py:74} INFO - Running command: ['bash', '-c', 'mkdir -p "/home/alxavier/Documents/airflowalura/semana=2022-12-19"']
[2022-12-28 18:54:26,281] {subprocess.py:85} INFO - Output:
[2022-12-28 18:54:26,287] {subprocess.py:96} INFO - Command exited with return code 0
[2022-12-28 18:54:26,340] {taskinstance.py:1395} INFO - Marking task as SUCCESS. dag_id=dados_climaticos, task_id=cria_pasta, execution_date=20221212T000000, start_date=20221228T215425, end_date=20221228T215426
[2022-12-28 18:54:26,460] {local_task_job.py:156} INFO - Task exited with return code 0
[2022-12-28 18:54:26,556] {local_task_job.py:273} INFO - 1 downstream tasks scheduled from follow-on schedule check
