[2022-12-28 18:29:18,594] {taskinstance.py:1159} INFO - Dependencies all met for <TaskInstance: dados_climaticos.extrai_dados scheduled__2022-10-10T00:00:00+00:00 [queued]>
[2022-12-28 18:29:18,607] {taskinstance.py:1159} INFO - Dependencies all met for <TaskInstance: dados_climaticos.extrai_dados scheduled__2022-10-10T00:00:00+00:00 [queued]>
[2022-12-28 18:29:18,607] {taskinstance.py:1356} INFO - 
--------------------------------------------------------------------------------
[2022-12-28 18:29:18,607] {taskinstance.py:1357} INFO - Starting attempt 1 of 1
[2022-12-28 18:29:18,608] {taskinstance.py:1358} INFO - 
--------------------------------------------------------------------------------
[2022-12-28 18:29:18,637] {taskinstance.py:1377} INFO - Executing <Task(PythonOperator): extrai_dados> on 2022-10-10 00:00:00+00:00
[2022-12-28 18:29:18,643] {standard_task_runner.py:52} INFO - Started process 18509 to run task
[2022-12-28 18:29:18,650] {standard_task_runner.py:79} INFO - Running: ['airflow', 'tasks', 'run', 'dados_climaticos', 'extrai_dados', 'scheduled__2022-10-10T00:00:00+00:00', '--job-id', '27', '--raw', '--subdir', 'DAGS_FOLDER/dados_climaticos.py', '--cfg-path', '/tmp/tmpvbsujgmq', '--error-file', '/tmp/tmp6zuykxjr']
[2022-12-28 18:29:18,657] {standard_task_runner.py:80} INFO - Job 27: Subtask extrai_dados
[2022-12-28 18:29:18,763] {task_command.py:370} INFO - Running <TaskInstance: dados_climaticos.extrai_dados scheduled__2022-10-10T00:00:00+00:00 [running]> on host alxavier-airflow
[2022-12-28 18:29:18,847] {taskinstance.py:1889} ERROR - Task failed with exception
Traceback (most recent call last):
  File "/home/alxavier/Documents/airflowalura/venv/lib/python3.9/site-packages/airflow/models/taskinstance.py", line 1451, in _run_raw_task
    self._execute_task_with_callbacks(context, test_mode)
  File "/home/alxavier/Documents/airflowalura/venv/lib/python3.9/site-packages/airflow/models/taskinstance.py", line 1555, in _execute_task_with_callbacks
    task_orig = self.render_templates(context=context)
  File "/home/alxavier/Documents/airflowalura/venv/lib/python3.9/site-packages/airflow/models/taskinstance.py", line 2212, in render_templates
    rendered_task = self.task.render_template_fields(context)
  File "/home/alxavier/Documents/airflowalura/venv/lib/python3.9/site-packages/airflow/models/baseoperator.py", line 1185, in render_template_fields
    self._do_render_template_fields(self, self.template_fields, context, jinja_env, set())
  File "/home/alxavier/Documents/airflowalura/venv/lib/python3.9/site-packages/airflow/utils/session.py", line 71, in wrapper
    return func(*args, session=session, **kwargs)
  File "/home/alxavier/Documents/airflowalura/venv/lib/python3.9/site-packages/airflow/models/abstractoperator.py", line 344, in _do_render_template_fields
    rendered_content = self.render_template(
  File "/home/alxavier/Documents/airflowalura/venv/lib/python3.9/site-packages/airflow/models/abstractoperator.py", line 404, in render_template
    return {key: self.render_template(value, context, jinja_env) for key, value in value.items()}
  File "/home/alxavier/Documents/airflowalura/venv/lib/python3.9/site-packages/airflow/models/abstractoperator.py", line 404, in <dictcomp>
    return {key: self.render_template(value, context, jinja_env) for key, value in value.items()}
  File "/home/alxavier/Documents/airflowalura/venv/lib/python3.9/site-packages/airflow/models/abstractoperator.py", line 387, in render_template
    template = jinja_env.from_string(value)
  File "/home/alxavier/Documents/airflowalura/venv/lib/python3.9/site-packages/jinja2/environment.py", line 1092, in from_string
    return cls.from_code(self, self.compile(source), gs, None)
  File "/home/alxavier/Documents/airflowalura/venv/lib/python3.9/site-packages/jinja2/environment.py", line 757, in compile
    self.handle_exception(source=source_hint)
  File "/home/alxavier/Documents/airflowalura/venv/lib/python3.9/site-packages/jinja2/environment.py", line 925, in handle_exception
    raise rewrite_traceback_stack(source=source)
  File "<unknown>", line 1, in template
jinja2.exceptions.TemplateSyntaxError: unexpected char '"' at 29
[2022-12-28 18:29:18,862] {taskinstance.py:1395} INFO - Marking task as FAILED. dag_id=dados_climaticos, task_id=extrai_dados, execution_date=20221010T000000, start_date=20221228T212918, end_date=20221228T212918
[2022-12-28 18:29:18,916] {standard_task_runner.py:92} ERROR - Failed to execute job 27 for task extrai_dados (unexpected char '"' at 29; 18509)
[2022-12-28 18:29:18,948] {local_task_job.py:156} INFO - Task exited with return code 1
[2022-12-28 18:29:18,983] {local_task_job.py:273} INFO - 0 downstream tasks scheduled from follow-on schedule check
[2022-12-28 18:45:34,500] {taskinstance.py:1159} INFO - Dependencies all met for <TaskInstance: dados_climaticos.extrai_dados scheduled__2022-10-10T00:00:00+00:00 [queued]>
[2022-12-28 18:45:34,536] {taskinstance.py:1159} INFO - Dependencies all met for <TaskInstance: dados_climaticos.extrai_dados scheduled__2022-10-10T00:00:00+00:00 [queued]>
[2022-12-28 18:45:34,536] {taskinstance.py:1356} INFO - 
--------------------------------------------------------------------------------
[2022-12-28 18:45:34,541] {taskinstance.py:1357} INFO - Starting attempt 1 of 1
[2022-12-28 18:45:34,547] {taskinstance.py:1358} INFO - 
--------------------------------------------------------------------------------
[2022-12-28 18:45:34,629] {taskinstance.py:1377} INFO - Executing <Task(PythonOperator): extrai_dados> on 2022-10-10 00:00:00+00:00
[2022-12-28 18:45:34,635] {standard_task_runner.py:52} INFO - Started process 20267 to run task
[2022-12-28 18:45:34,645] {standard_task_runner.py:79} INFO - Running: ['airflow', 'tasks', 'run', 'dados_climaticos', 'extrai_dados', 'scheduled__2022-10-10T00:00:00+00:00', '--job-id', '27', '--raw', '--subdir', 'DAGS_FOLDER/dados_climaticos.py', '--cfg-path', '/tmp/tmp7jl6atmp', '--error-file', '/tmp/tmpumqkpwjj']
[2022-12-28 18:45:34,646] {standard_task_runner.py:80} INFO - Job 27: Subtask extrai_dados
[2022-12-28 18:45:34,822] {task_command.py:370} INFO - Running <TaskInstance: dados_climaticos.extrai_dados scheduled__2022-10-10T00:00:00+00:00 [running]> on host alxavier-airflow
[2022-12-28 18:45:34,981] {taskinstance.py:1569} INFO - Exporting the following env vars:
AIRFLOW_CTX_DAG_OWNER=airflow
AIRFLOW_CTX_DAG_ID=dados_climaticos
AIRFLOW_CTX_TASK_ID=extrai_dados
AIRFLOW_CTX_EXECUTION_DATE=2022-10-10T00:00:00+00:00
AIRFLOW_CTX_TRY_NUMBER=1
AIRFLOW_CTX_DAG_RUN_ID=scheduled__2022-10-10T00:00:00+00:00
[2022-12-28 18:45:35,998] {taskinstance.py:1889} ERROR - Task failed with exception
Traceback (most recent call last):
  File "/home/alxavier/Documents/airflowalura/venv/lib/python3.9/site-packages/airflow/operators/python.py", line 171, in execute
    return_value = self.execute_callable()
  File "/home/alxavier/Documents/airflowalura/venv/lib/python3.9/site-packages/airflow/operators/python.py", line 189, in execute_callable
    return self.python_callable(*self.op_args, **self.op_kwargs)
  File "/home/alxavier/Documents/airflowalura/dags/dados_climaticos.py", line 33, in extrai_dados
    dados.to_csv(file_path + 'dados_brutos.csv')
  File "/home/alxavier/Documents/airflowalura/venv/lib/python3.9/site-packages/pandas/util/_decorators.py", line 211, in wrapper
    return func(*args, **kwargs)
  File "/home/alxavier/Documents/airflowalura/venv/lib/python3.9/site-packages/pandas/core/generic.py", line 3720, in to_csv
    return DataFrameRenderer(formatter).to_csv(
  File "/home/alxavier/Documents/airflowalura/venv/lib/python3.9/site-packages/pandas/util/_decorators.py", line 211, in wrapper
    return func(*args, **kwargs)
  File "/home/alxavier/Documents/airflowalura/venv/lib/python3.9/site-packages/pandas/io/formats/format.py", line 1189, in to_csv
    csv_formatter.save()
  File "/home/alxavier/Documents/airflowalura/venv/lib/python3.9/site-packages/pandas/io/formats/csvs.py", line 241, in save
    with get_handle(
  File "/home/alxavier/Documents/airflowalura/venv/lib/python3.9/site-packages/pandas/io/common.py", line 734, in get_handle
    check_parent_directory(str(handle))
  File "/home/alxavier/Documents/airflowalura/venv/lib/python3.9/site-packages/pandas/io/common.py", line 597, in check_parent_directory
    raise OSError(rf"Cannot save file into a non-existent directory: '{parent}'")
OSError: Cannot save file into a non-existent directory: '/home/alxavier/Documents/airflowalura/semana={data_interval_end}'
[2022-12-28 18:45:36,014] {taskinstance.py:1395} INFO - Marking task as FAILED. dag_id=dados_climaticos, task_id=extrai_dados, execution_date=20221010T000000, start_date=20221228T214534, end_date=20221228T214536
[2022-12-28 18:45:36,064] {standard_task_runner.py:92} ERROR - Failed to execute job 27 for task extrai_dados (Cannot save file into a non-existent directory: '/home/alxavier/Documents/airflowalura/semana={data_interval_end}'; 20267)
[2022-12-28 18:45:36,111] {local_task_job.py:156} INFO - Task exited with return code 1
[2022-12-28 18:45:36,176] {local_task_job.py:273} INFO - 0 downstream tasks scheduled from follow-on schedule check
[2022-12-28 18:52:57,772] {taskinstance.py:1159} INFO - Dependencies all met for <TaskInstance: dados_climaticos.extrai_dados scheduled__2022-10-10T00:00:00+00:00 [queued]>
[2022-12-28 18:52:57,787] {taskinstance.py:1159} INFO - Dependencies all met for <TaskInstance: dados_climaticos.extrai_dados scheduled__2022-10-10T00:00:00+00:00 [queued]>
[2022-12-28 18:52:57,787] {taskinstance.py:1356} INFO - 
--------------------------------------------------------------------------------
[2022-12-28 18:52:57,787] {taskinstance.py:1357} INFO - Starting attempt 1 of 1
[2022-12-28 18:52:57,788] {taskinstance.py:1358} INFO - 
--------------------------------------------------------------------------------
[2022-12-28 18:52:57,827] {taskinstance.py:1377} INFO - Executing <Task(PythonOperator): extrai_dados> on 2022-10-10 00:00:00+00:00
[2022-12-28 18:52:57,837] {standard_task_runner.py:52} INFO - Started process 21090 to run task
[2022-12-28 18:52:57,857] {standard_task_runner.py:79} INFO - Running: ['airflow', 'tasks', 'run', 'dados_climaticos', 'extrai_dados', 'scheduled__2022-10-10T00:00:00+00:00', '--job-id', '27', '--raw', '--subdir', 'DAGS_FOLDER/dados_climaticos.py', '--cfg-path', '/tmp/tmpgnw9hag6', '--error-file', '/tmp/tmpnf8sagxo']
[2022-12-28 18:52:57,860] {standard_task_runner.py:80} INFO - Job 27: Subtask extrai_dados
[2022-12-28 18:52:57,978] {task_command.py:370} INFO - Running <TaskInstance: dados_climaticos.extrai_dados scheduled__2022-10-10T00:00:00+00:00 [running]> on host alxavier-airflow
[2022-12-28 18:52:58,125] {taskinstance.py:1569} INFO - Exporting the following env vars:
AIRFLOW_CTX_DAG_OWNER=airflow
AIRFLOW_CTX_DAG_ID=dados_climaticos
AIRFLOW_CTX_TASK_ID=extrai_dados
AIRFLOW_CTX_EXECUTION_DATE=2022-10-10T00:00:00+00:00
AIRFLOW_CTX_TRY_NUMBER=1
AIRFLOW_CTX_DAG_RUN_ID=scheduled__2022-10-10T00:00:00+00:00
[2022-12-28 18:52:59,093] {python.py:173} INFO - Done. Returned value was: None
[2022-12-28 18:52:59,128] {taskinstance.py:1395} INFO - Marking task as SUCCESS. dag_id=dados_climaticos, task_id=extrai_dados, execution_date=20221010T000000, start_date=20221228T215257, end_date=20221228T215259
[2022-12-28 18:52:59,196] {local_task_job.py:156} INFO - Task exited with return code 0
[2022-12-28 18:52:59,229] {local_task_job.py:273} INFO - 0 downstream tasks scheduled from follow-on schedule check
