[2022-12-28 18:28:49,670] {taskinstance.py:1159} INFO - Dependencies all met for <TaskInstance: dados_climaticos.extrai_dados scheduled__2022-09-19T00:00:00+00:00 [queued]>
[2022-12-28 18:28:49,708] {taskinstance.py:1159} INFO - Dependencies all met for <TaskInstance: dados_climaticos.extrai_dados scheduled__2022-09-19T00:00:00+00:00 [queued]>
[2022-12-28 18:28:49,708] {taskinstance.py:1356} INFO - 
--------------------------------------------------------------------------------
[2022-12-28 18:28:49,708] {taskinstance.py:1357} INFO - Starting attempt 1 of 1
[2022-12-28 18:28:49,708] {taskinstance.py:1358} INFO - 
--------------------------------------------------------------------------------
[2022-12-28 18:28:49,748] {taskinstance.py:1377} INFO - Executing <Task(PythonOperator): extrai_dados> on 2022-09-19 00:00:00+00:00
[2022-12-28 18:28:49,757] {standard_task_runner.py:52} INFO - Started process 18460 to run task
[2022-12-28 18:28:49,764] {standard_task_runner.py:79} INFO - Running: ['airflow', 'tasks', 'run', 'dados_climaticos', 'extrai_dados', 'scheduled__2022-09-19T00:00:00+00:00', '--job-id', '21', '--raw', '--subdir', 'DAGS_FOLDER/dados_climaticos.py', '--cfg-path', '/tmp/tmp9henr9gj', '--error-file', '/tmp/tmpfn8050pl']
[2022-12-28 18:28:49,780] {standard_task_runner.py:80} INFO - Job 21: Subtask extrai_dados
[2022-12-28 18:28:49,967] {task_command.py:370} INFO - Running <TaskInstance: dados_climaticos.extrai_dados scheduled__2022-09-19T00:00:00+00:00 [running]> on host alxavier-airflow
[2022-12-28 18:28:50,041] {taskinstance.py:1889} ERROR - Task failed with exception
Traceback (most recent call last):
  File "/home/alxavier/Documents/airflowalura/venv/lib/python3.9/site-packages/airflow/models/taskinstance.py", line 1451, in _run_raw_task
    self._execute_task_with_callbacks(context, test_mode)
  File "/home/alxavier/Documents/airflowalura/venv/lib/python3.9/site-packages/airflow/models/taskinstance.py", line 1555, in _execute_task_with_callbacks
    task_orig = self.render_templates(context=context)
  File "/home/alxavier/Documents/airflowalura/venv/lib/python3.9/site-packages/airflow/models/taskinstance.py", line 2212, in render_templates
    rendered_task = self.task.render_template_fields(context)
  File "/home/alxavier/Documents/airflowalura/venv/lib/python3.9/site-packages/airflow/models/baseoperator.py", line 1185, in render_template_fields
    self._do_render_template_fields(self, self.template_fields, context, jinja_env, set())
  File "/home/alxavier/Documents/airflowalura/venv/lib/python3.9/site-packages/airflow/utils/session.py", line 71, in wrapper
    return func(*args, session=session, **kwargs)
  File "/home/alxavier/Documents/airflowalura/venv/lib/python3.9/site-packages/airflow/models/abstractoperator.py", line 344, in _do_render_template_fields
    rendered_content = self.render_template(
  File "/home/alxavier/Documents/airflowalura/venv/lib/python3.9/site-packages/airflow/models/abstractoperator.py", line 404, in render_template
    return {key: self.render_template(value, context, jinja_env) for key, value in value.items()}
  File "/home/alxavier/Documents/airflowalura/venv/lib/python3.9/site-packages/airflow/models/abstractoperator.py", line 404, in <dictcomp>
    return {key: self.render_template(value, context, jinja_env) for key, value in value.items()}
  File "/home/alxavier/Documents/airflowalura/venv/lib/python3.9/site-packages/airflow/models/abstractoperator.py", line 387, in render_template
    template = jinja_env.from_string(value)
  File "/home/alxavier/Documents/airflowalura/venv/lib/python3.9/site-packages/jinja2/environment.py", line 1092, in from_string
    return cls.from_code(self, self.compile(source), gs, None)
  File "/home/alxavier/Documents/airflowalura/venv/lib/python3.9/site-packages/jinja2/environment.py", line 757, in compile
    self.handle_exception(source=source_hint)
  File "/home/alxavier/Documents/airflowalura/venv/lib/python3.9/site-packages/jinja2/environment.py", line 925, in handle_exception
    raise rewrite_traceback_stack(source=source)
  File "<unknown>", line 1, in template
jinja2.exceptions.TemplateSyntaxError: unexpected char '"' at 29
[2022-12-28 18:28:50,052] {taskinstance.py:1395} INFO - Marking task as FAILED. dag_id=dados_climaticos, task_id=extrai_dados, execution_date=20220919T000000, start_date=20221228T212849, end_date=20221228T212850
[2022-12-28 18:28:50,089] {standard_task_runner.py:92} ERROR - Failed to execute job 21 for task extrai_dados (unexpected char '"' at 29; 18460)
[2022-12-28 18:28:50,134] {local_task_job.py:156} INFO - Task exited with return code 1
[2022-12-28 18:28:50,183] {local_task_job.py:273} INFO - 0 downstream tasks scheduled from follow-on schedule check
[2022-12-28 18:38:23,775] {taskinstance.py:1159} INFO - Dependencies all met for <TaskInstance: dados_climaticos.extrai_dados scheduled__2022-09-19T00:00:00+00:00 [queued]>
[2022-12-28 18:38:23,792] {taskinstance.py:1159} INFO - Dependencies all met for <TaskInstance: dados_climaticos.extrai_dados scheduled__2022-09-19T00:00:00+00:00 [queued]>
[2022-12-28 18:38:23,792] {taskinstance.py:1356} INFO - 
--------------------------------------------------------------------------------
[2022-12-28 18:38:23,792] {taskinstance.py:1357} INFO - Starting attempt 1 of 1
[2022-12-28 18:38:23,793] {taskinstance.py:1358} INFO - 
--------------------------------------------------------------------------------
[2022-12-28 18:38:23,867] {taskinstance.py:1377} INFO - Executing <Task(PythonOperator): extrai_dados> on 2022-09-19 00:00:00+00:00
[2022-12-28 18:38:23,880] {standard_task_runner.py:52} INFO - Started process 19490 to run task
[2022-12-28 18:38:23,894] {standard_task_runner.py:79} INFO - Running: ['airflow', 'tasks', 'run', 'dados_climaticos', 'extrai_dados', 'scheduled__2022-09-19T00:00:00+00:00', '--job-id', '21', '--raw', '--subdir', 'DAGS_FOLDER/dados_climaticos.py', '--cfg-path', '/tmp/tmpsu29a82g', '--error-file', '/tmp/tmpww240mih']
[2022-12-28 18:38:23,902] {standard_task_runner.py:80} INFO - Job 21: Subtask extrai_dados
[2022-12-28 18:38:24,137] {task_command.py:370} INFO - Running <TaskInstance: dados_climaticos.extrai_dados scheduled__2022-09-19T00:00:00+00:00 [running]> on host alxavier-airflow
[2022-12-28 18:38:24,485] {taskinstance.py:1569} INFO - Exporting the following env vars:
AIRFLOW_CTX_DAG_OWNER=airflow
AIRFLOW_CTX_DAG_ID=dados_climaticos
AIRFLOW_CTX_TASK_ID=extrai_dados
AIRFLOW_CTX_EXECUTION_DATE=2022-09-19T00:00:00+00:00
AIRFLOW_CTX_TRY_NUMBER=1
AIRFLOW_CTX_DAG_RUN_ID=scheduled__2022-09-19T00:00:00+00:00
[2022-12-28 18:38:24,488] {taskinstance.py:1889} ERROR - Task failed with exception
Traceback (most recent call last):
  File "/home/alxavier/Documents/airflowalura/venv/lib/python3.9/site-packages/airflow/operators/python.py", line 171, in execute
    return_value = self.execute_callable()
  File "/home/alxavier/Documents/airflowalura/venv/lib/python3.9/site-packages/airflow/operators/python.py", line 189, in execute_callable
    return self.python_callable(*self.op_args, **self.op_kwargs)
  File "/home/alxavier/Documents/airflowalura/dags/dados_climaticos.py", line 27, in extrai_dados
    f'{city}/{data_interval_end}/{ds_add(data_interval_end, 7)}?unitGroup=metric&include=days&key={key}&contentType=csv')
  File "/home/alxavier/Documents/airflowalura/venv/lib/python3.9/site-packages/airflow/macros/__init__.py", line 44, in ds_add
    dt = datetime.strptime(str(ds), "%Y-%m-%d") + timedelta(days=days)
  File "/usr/lib/python3.9/_strptime.py", line 568, in _strptime_datetime
    tt, fraction, gmtoff_fraction = _strptime(data_string, format)
  File "/usr/lib/python3.9/_strptime.py", line 349, in _strptime
    raise ValueError("time data %r does not match format %r" %
ValueError: time data '2022-09_26' does not match format '%Y-%m-%d'
[2022-12-28 18:38:24,558] {taskinstance.py:1395} INFO - Marking task as FAILED. dag_id=dados_climaticos, task_id=extrai_dados, execution_date=20220919T000000, start_date=20221228T213823, end_date=20221228T213824
[2022-12-28 18:38:24,613] {standard_task_runner.py:92} ERROR - Failed to execute job 21 for task extrai_dados (time data '2022-09_26' does not match format '%Y-%m-%d'; 19490)
[2022-12-28 18:38:24,653] {local_task_job.py:156} INFO - Task exited with return code 1
[2022-12-28 18:38:24,740] {local_task_job.py:273} INFO - 0 downstream tasks scheduled from follow-on schedule check
[2022-12-28 18:42:41,760] {taskinstance.py:1159} INFO - Dependencies all met for <TaskInstance: dados_climaticos.extrai_dados scheduled__2022-09-19T00:00:00+00:00 [queued]>
[2022-12-28 18:42:41,834] {taskinstance.py:1159} INFO - Dependencies all met for <TaskInstance: dados_climaticos.extrai_dados scheduled__2022-09-19T00:00:00+00:00 [queued]>
[2022-12-28 18:42:41,834] {taskinstance.py:1356} INFO - 
--------------------------------------------------------------------------------
[2022-12-28 18:42:41,834] {taskinstance.py:1357} INFO - Starting attempt 1 of 1
[2022-12-28 18:42:41,834] {taskinstance.py:1358} INFO - 
--------------------------------------------------------------------------------
[2022-12-28 18:42:42,126] {taskinstance.py:1377} INFO - Executing <Task(PythonOperator): extrai_dados> on 2022-09-19 00:00:00+00:00
[2022-12-28 18:42:42,136] {standard_task_runner.py:52} INFO - Started process 19942 to run task
[2022-12-28 18:42:42,161] {standard_task_runner.py:79} INFO - Running: ['airflow', 'tasks', 'run', 'dados_climaticos', 'extrai_dados', 'scheduled__2022-09-19T00:00:00+00:00', '--job-id', '21', '--raw', '--subdir', 'DAGS_FOLDER/dados_climaticos.py', '--cfg-path', '/tmp/tmpuzdkux9y', '--error-file', '/tmp/tmpix_3mleb']
[2022-12-28 18:42:42,182] {standard_task_runner.py:80} INFO - Job 21: Subtask extrai_dados
[2022-12-28 18:42:42,385] {task_command.py:370} INFO - Running <TaskInstance: dados_climaticos.extrai_dados scheduled__2022-09-19T00:00:00+00:00 [running]> on host alxavier-airflow
[2022-12-28 18:42:42,523] {taskinstance.py:1569} INFO - Exporting the following env vars:
AIRFLOW_CTX_DAG_OWNER=airflow
AIRFLOW_CTX_DAG_ID=dados_climaticos
AIRFLOW_CTX_TASK_ID=extrai_dados
AIRFLOW_CTX_EXECUTION_DATE=2022-09-19T00:00:00+00:00
AIRFLOW_CTX_TRY_NUMBER=1
AIRFLOW_CTX_DAG_RUN_ID=scheduled__2022-09-19T00:00:00+00:00
[2022-12-28 18:42:43,567] {taskinstance.py:1889} ERROR - Task failed with exception
Traceback (most recent call last):
  File "/home/alxavier/Documents/airflowalura/venv/lib/python3.9/site-packages/airflow/operators/python.py", line 171, in execute
    return_value = self.execute_callable()
  File "/home/alxavier/Documents/airflowalura/venv/lib/python3.9/site-packages/airflow/operators/python.py", line 189, in execute_callable
    return self.python_callable(*self.op_args, **self.op_kwargs)
  File "/home/alxavier/Documents/airflowalura/dags/dados_climaticos.py", line 33, in extrai_dados
    dados.to_csv(file_path + 'dados_brutos.csv')
  File "/home/alxavier/Documents/airflowalura/venv/lib/python3.9/site-packages/pandas/util/_decorators.py", line 211, in wrapper
    return func(*args, **kwargs)
  File "/home/alxavier/Documents/airflowalura/venv/lib/python3.9/site-packages/pandas/core/generic.py", line 3720, in to_csv
    return DataFrameRenderer(formatter).to_csv(
  File "/home/alxavier/Documents/airflowalura/venv/lib/python3.9/site-packages/pandas/util/_decorators.py", line 211, in wrapper
    return func(*args, **kwargs)
  File "/home/alxavier/Documents/airflowalura/venv/lib/python3.9/site-packages/pandas/io/formats/format.py", line 1189, in to_csv
    csv_formatter.save()
  File "/home/alxavier/Documents/airflowalura/venv/lib/python3.9/site-packages/pandas/io/formats/csvs.py", line 241, in save
    with get_handle(
  File "/home/alxavier/Documents/airflowalura/venv/lib/python3.9/site-packages/pandas/io/common.py", line 734, in get_handle
    check_parent_directory(str(handle))
  File "/home/alxavier/Documents/airflowalura/venv/lib/python3.9/site-packages/pandas/io/common.py", line 597, in check_parent_directory
    raise OSError(rf"Cannot save file into a non-existent directory: '{parent}'")
OSError: Cannot save file into a non-existent directory: '/home/alxavier/Documents/airflowalura/semana={data_interval_end}'
[2022-12-28 18:42:43,605] {taskinstance.py:1395} INFO - Marking task as FAILED. dag_id=dados_climaticos, task_id=extrai_dados, execution_date=20220919T000000, start_date=20221228T214241, end_date=20221228T214243
[2022-12-28 18:42:43,680] {standard_task_runner.py:92} ERROR - Failed to execute job 21 for task extrai_dados (Cannot save file into a non-existent directory: '/home/alxavier/Documents/airflowalura/semana={data_interval_end}'; 19942)
[2022-12-28 18:42:43,731] {local_task_job.py:156} INFO - Task exited with return code 1
[2022-12-28 18:42:43,895] {local_task_job.py:273} INFO - 0 downstream tasks scheduled from follow-on schedule check
[2022-12-28 18:44:57,706] {taskinstance.py:1159} INFO - Dependencies all met for <TaskInstance: dados_climaticos.extrai_dados scheduled__2022-09-19T00:00:00+00:00 [queued]>
[2022-12-28 18:44:57,725] {taskinstance.py:1159} INFO - Dependencies all met for <TaskInstance: dados_climaticos.extrai_dados scheduled__2022-09-19T00:00:00+00:00 [queued]>
[2022-12-28 18:44:57,725] {taskinstance.py:1356} INFO - 
--------------------------------------------------------------------------------
[2022-12-28 18:44:57,725] {taskinstance.py:1357} INFO - Starting attempt 1 of 1
[2022-12-28 18:44:57,726] {taskinstance.py:1358} INFO - 
--------------------------------------------------------------------------------
[2022-12-28 18:44:57,778] {taskinstance.py:1377} INFO - Executing <Task(PythonOperator): extrai_dados> on 2022-09-19 00:00:00+00:00
[2022-12-28 18:44:57,786] {standard_task_runner.py:52} INFO - Started process 20210 to run task
[2022-12-28 18:44:57,813] {standard_task_runner.py:79} INFO - Running: ['airflow', 'tasks', 'run', 'dados_climaticos', 'extrai_dados', 'scheduled__2022-09-19T00:00:00+00:00', '--job-id', '21', '--raw', '--subdir', 'DAGS_FOLDER/dados_climaticos.py', '--cfg-path', '/tmp/tmpmtjf9mhw', '--error-file', '/tmp/tmpiwklzbr0']
[2022-12-28 18:44:57,814] {standard_task_runner.py:80} INFO - Job 21: Subtask extrai_dados
[2022-12-28 18:44:57,985] {task_command.py:370} INFO - Running <TaskInstance: dados_climaticos.extrai_dados scheduled__2022-09-19T00:00:00+00:00 [running]> on host alxavier-airflow
[2022-12-28 18:44:58,126] {taskinstance.py:1569} INFO - Exporting the following env vars:
AIRFLOW_CTX_DAG_OWNER=airflow
AIRFLOW_CTX_DAG_ID=dados_climaticos
AIRFLOW_CTX_TASK_ID=extrai_dados
AIRFLOW_CTX_EXECUTION_DATE=2022-09-19T00:00:00+00:00
AIRFLOW_CTX_TRY_NUMBER=1
AIRFLOW_CTX_DAG_RUN_ID=scheduled__2022-09-19T00:00:00+00:00
[2022-12-28 18:44:59,029] {taskinstance.py:1889} ERROR - Task failed with exception
Traceback (most recent call last):
  File "/home/alxavier/Documents/airflowalura/venv/lib/python3.9/site-packages/airflow/operators/python.py", line 171, in execute
    return_value = self.execute_callable()
  File "/home/alxavier/Documents/airflowalura/venv/lib/python3.9/site-packages/airflow/operators/python.py", line 189, in execute_callable
    return self.python_callable(*self.op_args, **self.op_kwargs)
  File "/home/alxavier/Documents/airflowalura/dags/dados_climaticos.py", line 33, in extrai_dados
    dados.to_csv(file_path + 'dados_brutos.csv')
  File "/home/alxavier/Documents/airflowalura/venv/lib/python3.9/site-packages/pandas/util/_decorators.py", line 211, in wrapper
    return func(*args, **kwargs)
  File "/home/alxavier/Documents/airflowalura/venv/lib/python3.9/site-packages/pandas/core/generic.py", line 3720, in to_csv
    return DataFrameRenderer(formatter).to_csv(
  File "/home/alxavier/Documents/airflowalura/venv/lib/python3.9/site-packages/pandas/util/_decorators.py", line 211, in wrapper
    return func(*args, **kwargs)
  File "/home/alxavier/Documents/airflowalura/venv/lib/python3.9/site-packages/pandas/io/formats/format.py", line 1189, in to_csv
    csv_formatter.save()
  File "/home/alxavier/Documents/airflowalura/venv/lib/python3.9/site-packages/pandas/io/formats/csvs.py", line 241, in save
    with get_handle(
  File "/home/alxavier/Documents/airflowalura/venv/lib/python3.9/site-packages/pandas/io/common.py", line 734, in get_handle
    check_parent_directory(str(handle))
  File "/home/alxavier/Documents/airflowalura/venv/lib/python3.9/site-packages/pandas/io/common.py", line 597, in check_parent_directory
    raise OSError(rf"Cannot save file into a non-existent directory: '{parent}'")
OSError: Cannot save file into a non-existent directory: '/home/alxavier/Documents/airflowalura/semana={data_interval_end}'
[2022-12-28 18:44:59,046] {taskinstance.py:1395} INFO - Marking task as FAILED. dag_id=dados_climaticos, task_id=extrai_dados, execution_date=20220919T000000, start_date=20221228T214457, end_date=20221228T214459
[2022-12-28 18:44:59,083] {standard_task_runner.py:92} ERROR - Failed to execute job 21 for task extrai_dados (Cannot save file into a non-existent directory: '/home/alxavier/Documents/airflowalura/semana={data_interval_end}'; 20210)
[2022-12-28 18:44:59,123] {local_task_job.py:156} INFO - Task exited with return code 1
[2022-12-28 18:44:59,191] {local_task_job.py:273} INFO - 0 downstream tasks scheduled from follow-on schedule check
[2022-12-28 18:52:26,355] {taskinstance.py:1159} INFO - Dependencies all met for <TaskInstance: dados_climaticos.extrai_dados scheduled__2022-09-19T00:00:00+00:00 [queued]>
[2022-12-28 18:52:26,370] {taskinstance.py:1159} INFO - Dependencies all met for <TaskInstance: dados_climaticos.extrai_dados scheduled__2022-09-19T00:00:00+00:00 [queued]>
[2022-12-28 18:52:26,370] {taskinstance.py:1356} INFO - 
--------------------------------------------------------------------------------
[2022-12-28 18:52:26,370] {taskinstance.py:1357} INFO - Starting attempt 1 of 1
[2022-12-28 18:52:26,370] {taskinstance.py:1358} INFO - 
--------------------------------------------------------------------------------
[2022-12-28 18:52:26,411] {taskinstance.py:1377} INFO - Executing <Task(PythonOperator): extrai_dados> on 2022-09-19 00:00:00+00:00
[2022-12-28 18:52:26,418] {standard_task_runner.py:52} INFO - Started process 21027 to run task
[2022-12-28 18:52:26,431] {standard_task_runner.py:79} INFO - Running: ['airflow', 'tasks', 'run', 'dados_climaticos', 'extrai_dados', 'scheduled__2022-09-19T00:00:00+00:00', '--job-id', '21', '--raw', '--subdir', 'DAGS_FOLDER/dados_climaticos.py', '--cfg-path', '/tmp/tmpnnmpv163', '--error-file', '/tmp/tmp2mq4s3j3']
[2022-12-28 18:52:26,436] {standard_task_runner.py:80} INFO - Job 21: Subtask extrai_dados
[2022-12-28 18:52:26,585] {task_command.py:370} INFO - Running <TaskInstance: dados_climaticos.extrai_dados scheduled__2022-09-19T00:00:00+00:00 [running]> on host alxavier-airflow
[2022-12-28 18:52:26,684] {taskinstance.py:1569} INFO - Exporting the following env vars:
AIRFLOW_CTX_DAG_OWNER=airflow
AIRFLOW_CTX_DAG_ID=dados_climaticos
AIRFLOW_CTX_TASK_ID=extrai_dados
AIRFLOW_CTX_EXECUTION_DATE=2022-09-19T00:00:00+00:00
AIRFLOW_CTX_TRY_NUMBER=1
AIRFLOW_CTX_DAG_RUN_ID=scheduled__2022-09-19T00:00:00+00:00
[2022-12-28 18:52:27,840] {python.py:173} INFO - Done. Returned value was: None
[2022-12-28 18:52:27,859] {taskinstance.py:1395} INFO - Marking task as SUCCESS. dag_id=dados_climaticos, task_id=extrai_dados, execution_date=20220919T000000, start_date=20221228T215226, end_date=20221228T215227
[2022-12-28 18:52:27,960] {local_task_job.py:156} INFO - Task exited with return code 0
[2022-12-28 18:52:28,014] {local_task_job.py:273} INFO - 0 downstream tasks scheduled from follow-on schedule check
