[2022-12-28 18:28:30,384] {taskinstance.py:1159} INFO - Dependencies all met for <TaskInstance: dados_climaticos.extrai_dados scheduled__2022-09-12T00:00:00+00:00 [queued]>
[2022-12-28 18:28:30,398] {taskinstance.py:1159} INFO - Dependencies all met for <TaskInstance: dados_climaticos.extrai_dados scheduled__2022-09-12T00:00:00+00:00 [queued]>
[2022-12-28 18:28:30,398] {taskinstance.py:1356} INFO - 
--------------------------------------------------------------------------------
[2022-12-28 18:28:30,398] {taskinstance.py:1357} INFO - Starting attempt 1 of 1
[2022-12-28 18:28:30,399] {taskinstance.py:1358} INFO - 
--------------------------------------------------------------------------------
[2022-12-28 18:28:30,478] {taskinstance.py:1377} INFO - Executing <Task(PythonOperator): extrai_dados> on 2022-09-12 00:00:00+00:00
[2022-12-28 18:28:30,484] {standard_task_runner.py:52} INFO - Started process 18425 to run task
[2022-12-28 18:28:30,497] {standard_task_runner.py:79} INFO - Running: ['airflow', 'tasks', 'run', 'dados_climaticos', 'extrai_dados', 'scheduled__2022-09-12T00:00:00+00:00', '--job-id', '18', '--raw', '--subdir', 'DAGS_FOLDER/dados_climaticos.py', '--cfg-path', '/tmp/tmp9u8n0126', '--error-file', '/tmp/tmp4es6h4wv']
[2022-12-28 18:28:30,528] {standard_task_runner.py:80} INFO - Job 18: Subtask extrai_dados
[2022-12-28 18:28:30,974] {task_command.py:370} INFO - Running <TaskInstance: dados_climaticos.extrai_dados scheduled__2022-09-12T00:00:00+00:00 [running]> on host alxavier-airflow
[2022-12-28 18:28:31,028] {taskinstance.py:1889} ERROR - Task failed with exception
Traceback (most recent call last):
  File "/home/alxavier/Documents/airflowalura/venv/lib/python3.9/site-packages/airflow/models/taskinstance.py", line 1451, in _run_raw_task
    self._execute_task_with_callbacks(context, test_mode)
  File "/home/alxavier/Documents/airflowalura/venv/lib/python3.9/site-packages/airflow/models/taskinstance.py", line 1555, in _execute_task_with_callbacks
    task_orig = self.render_templates(context=context)
  File "/home/alxavier/Documents/airflowalura/venv/lib/python3.9/site-packages/airflow/models/taskinstance.py", line 2212, in render_templates
    rendered_task = self.task.render_template_fields(context)
  File "/home/alxavier/Documents/airflowalura/venv/lib/python3.9/site-packages/airflow/models/baseoperator.py", line 1185, in render_template_fields
    self._do_render_template_fields(self, self.template_fields, context, jinja_env, set())
  File "/home/alxavier/Documents/airflowalura/venv/lib/python3.9/site-packages/airflow/utils/session.py", line 71, in wrapper
    return func(*args, session=session, **kwargs)
  File "/home/alxavier/Documents/airflowalura/venv/lib/python3.9/site-packages/airflow/models/abstractoperator.py", line 344, in _do_render_template_fields
    rendered_content = self.render_template(
  File "/home/alxavier/Documents/airflowalura/venv/lib/python3.9/site-packages/airflow/models/abstractoperator.py", line 404, in render_template
    return {key: self.render_template(value, context, jinja_env) for key, value in value.items()}
  File "/home/alxavier/Documents/airflowalura/venv/lib/python3.9/site-packages/airflow/models/abstractoperator.py", line 404, in <dictcomp>
    return {key: self.render_template(value, context, jinja_env) for key, value in value.items()}
  File "/home/alxavier/Documents/airflowalura/venv/lib/python3.9/site-packages/airflow/models/abstractoperator.py", line 387, in render_template
    template = jinja_env.from_string(value)
  File "/home/alxavier/Documents/airflowalura/venv/lib/python3.9/site-packages/jinja2/environment.py", line 1092, in from_string
    return cls.from_code(self, self.compile(source), gs, None)
  File "/home/alxavier/Documents/airflowalura/venv/lib/python3.9/site-packages/jinja2/environment.py", line 757, in compile
    self.handle_exception(source=source_hint)
  File "/home/alxavier/Documents/airflowalura/venv/lib/python3.9/site-packages/jinja2/environment.py", line 925, in handle_exception
    raise rewrite_traceback_stack(source=source)
  File "<unknown>", line 1, in template
jinja2.exceptions.TemplateSyntaxError: unexpected char '"' at 29
[2022-12-28 18:28:31,038] {taskinstance.py:1395} INFO - Marking task as FAILED. dag_id=dados_climaticos, task_id=extrai_dados, execution_date=20220912T000000, start_date=20221228T212830, end_date=20221228T212831
[2022-12-28 18:28:31,071] {standard_task_runner.py:92} ERROR - Failed to execute job 18 for task extrai_dados (unexpected char '"' at 29; 18425)
[2022-12-28 18:28:31,103] {local_task_job.py:156} INFO - Task exited with return code 1
[2022-12-28 18:28:31,150] {local_task_job.py:273} INFO - 0 downstream tasks scheduled from follow-on schedule check
[2022-12-28 18:38:12,476] {taskinstance.py:1159} INFO - Dependencies all met for <TaskInstance: dados_climaticos.extrai_dados scheduled__2022-09-12T00:00:00+00:00 [queued]>
[2022-12-28 18:38:12,509] {taskinstance.py:1159} INFO - Dependencies all met for <TaskInstance: dados_climaticos.extrai_dados scheduled__2022-09-12T00:00:00+00:00 [queued]>
[2022-12-28 18:38:12,511] {taskinstance.py:1356} INFO - 
--------------------------------------------------------------------------------
[2022-12-28 18:38:12,511] {taskinstance.py:1357} INFO - Starting attempt 1 of 1
[2022-12-28 18:38:12,512] {taskinstance.py:1358} INFO - 
--------------------------------------------------------------------------------
[2022-12-28 18:38:12,567] {taskinstance.py:1377} INFO - Executing <Task(PythonOperator): extrai_dados> on 2022-09-12 00:00:00+00:00
[2022-12-28 18:38:12,572] {standard_task_runner.py:52} INFO - Started process 19472 to run task
[2022-12-28 18:38:12,590] {standard_task_runner.py:79} INFO - Running: ['airflow', 'tasks', 'run', 'dados_climaticos', 'extrai_dados', 'scheduled__2022-09-12T00:00:00+00:00', '--job-id', '19', '--raw', '--subdir', 'DAGS_FOLDER/dados_climaticos.py', '--cfg-path', '/tmp/tmpmf_awfvk', '--error-file', '/tmp/tmpmblsvyn7']
[2022-12-28 18:38:12,592] {standard_task_runner.py:80} INFO - Job 19: Subtask extrai_dados
[2022-12-28 18:38:12,719] {task_command.py:370} INFO - Running <TaskInstance: dados_climaticos.extrai_dados scheduled__2022-09-12T00:00:00+00:00 [running]> on host alxavier-airflow
[2022-12-28 18:38:12,898] {taskinstance.py:1569} INFO - Exporting the following env vars:
AIRFLOW_CTX_DAG_OWNER=airflow
AIRFLOW_CTX_DAG_ID=dados_climaticos
AIRFLOW_CTX_TASK_ID=extrai_dados
AIRFLOW_CTX_EXECUTION_DATE=2022-09-12T00:00:00+00:00
AIRFLOW_CTX_TRY_NUMBER=1
AIRFLOW_CTX_DAG_RUN_ID=scheduled__2022-09-12T00:00:00+00:00
[2022-12-28 18:38:12,908] {taskinstance.py:1889} ERROR - Task failed with exception
Traceback (most recent call last):
  File "/home/alxavier/Documents/airflowalura/venv/lib/python3.9/site-packages/airflow/operators/python.py", line 171, in execute
    return_value = self.execute_callable()
  File "/home/alxavier/Documents/airflowalura/venv/lib/python3.9/site-packages/airflow/operators/python.py", line 189, in execute_callable
    return self.python_callable(*self.op_args, **self.op_kwargs)
  File "/home/alxavier/Documents/airflowalura/dags/dados_climaticos.py", line 27, in extrai_dados
    f'{city}/{data_interval_end}/{ds_add(data_interval_end, 7)}?unitGroup=metric&include=days&key={key}&contentType=csv')
  File "/home/alxavier/Documents/airflowalura/venv/lib/python3.9/site-packages/airflow/macros/__init__.py", line 44, in ds_add
    dt = datetime.strptime(str(ds), "%Y-%m-%d") + timedelta(days=days)
  File "/usr/lib/python3.9/_strptime.py", line 568, in _strptime_datetime
    tt, fraction, gmtoff_fraction = _strptime(data_string, format)
  File "/usr/lib/python3.9/_strptime.py", line 349, in _strptime
    raise ValueError("time data %r does not match format %r" %
ValueError: time data '2022-09_19' does not match format '%Y-%m-%d'
[2022-12-28 18:38:12,922] {taskinstance.py:1395} INFO - Marking task as FAILED. dag_id=dados_climaticos, task_id=extrai_dados, execution_date=20220912T000000, start_date=20221228T213812, end_date=20221228T213812
[2022-12-28 18:38:12,961] {standard_task_runner.py:92} ERROR - Failed to execute job 19 for task extrai_dados (time data '2022-09_19' does not match format '%Y-%m-%d'; 19472)
[2022-12-28 18:38:13,024] {local_task_job.py:156} INFO - Task exited with return code 1
[2022-12-28 18:38:13,142] {local_task_job.py:273} INFO - 0 downstream tasks scheduled from follow-on schedule check
[2022-12-28 18:42:29,983] {taskinstance.py:1159} INFO - Dependencies all met for <TaskInstance: dados_climaticos.extrai_dados scheduled__2022-09-12T00:00:00+00:00 [queued]>
[2022-12-28 18:42:30,009] {taskinstance.py:1159} INFO - Dependencies all met for <TaskInstance: dados_climaticos.extrai_dados scheduled__2022-09-12T00:00:00+00:00 [queued]>
[2022-12-28 18:42:30,009] {taskinstance.py:1356} INFO - 
--------------------------------------------------------------------------------
[2022-12-28 18:42:30,009] {taskinstance.py:1357} INFO - Starting attempt 1 of 1
[2022-12-28 18:42:30,009] {taskinstance.py:1358} INFO - 
--------------------------------------------------------------------------------
[2022-12-28 18:42:30,070] {taskinstance.py:1377} INFO - Executing <Task(PythonOperator): extrai_dados> on 2022-09-12 00:00:00+00:00
[2022-12-28 18:42:30,082] {standard_task_runner.py:52} INFO - Started process 19917 to run task
[2022-12-28 18:42:30,096] {standard_task_runner.py:79} INFO - Running: ['airflow', 'tasks', 'run', 'dados_climaticos', 'extrai_dados', 'scheduled__2022-09-12T00:00:00+00:00', '--job-id', '19', '--raw', '--subdir', 'DAGS_FOLDER/dados_climaticos.py', '--cfg-path', '/tmp/tmpd0vkwdbl', '--error-file', '/tmp/tmp8pni2jgs']
[2022-12-28 18:42:30,097] {standard_task_runner.py:80} INFO - Job 19: Subtask extrai_dados
[2022-12-28 18:42:30,220] {task_command.py:370} INFO - Running <TaskInstance: dados_climaticos.extrai_dados scheduled__2022-09-12T00:00:00+00:00 [running]> on host alxavier-airflow
[2022-12-28 18:42:30,435] {taskinstance.py:1569} INFO - Exporting the following env vars:
AIRFLOW_CTX_DAG_OWNER=airflow
AIRFLOW_CTX_DAG_ID=dados_climaticos
AIRFLOW_CTX_TASK_ID=extrai_dados
AIRFLOW_CTX_EXECUTION_DATE=2022-09-12T00:00:00+00:00
AIRFLOW_CTX_TRY_NUMBER=1
AIRFLOW_CTX_DAG_RUN_ID=scheduled__2022-09-12T00:00:00+00:00
[2022-12-28 18:42:31,481] {taskinstance.py:1889} ERROR - Task failed with exception
Traceback (most recent call last):
  File "/home/alxavier/Documents/airflowalura/venv/lib/python3.9/site-packages/airflow/operators/python.py", line 171, in execute
    return_value = self.execute_callable()
  File "/home/alxavier/Documents/airflowalura/venv/lib/python3.9/site-packages/airflow/operators/python.py", line 189, in execute_callable
    return self.python_callable(*self.op_args, **self.op_kwargs)
  File "/home/alxavier/Documents/airflowalura/dags/dados_climaticos.py", line 33, in extrai_dados
    dados.to_csv(file_path + 'dados_brutos.csv')
  File "/home/alxavier/Documents/airflowalura/venv/lib/python3.9/site-packages/pandas/util/_decorators.py", line 211, in wrapper
    return func(*args, **kwargs)
  File "/home/alxavier/Documents/airflowalura/venv/lib/python3.9/site-packages/pandas/core/generic.py", line 3720, in to_csv
    return DataFrameRenderer(formatter).to_csv(
  File "/home/alxavier/Documents/airflowalura/venv/lib/python3.9/site-packages/pandas/util/_decorators.py", line 211, in wrapper
    return func(*args, **kwargs)
  File "/home/alxavier/Documents/airflowalura/venv/lib/python3.9/site-packages/pandas/io/formats/format.py", line 1189, in to_csv
    csv_formatter.save()
  File "/home/alxavier/Documents/airflowalura/venv/lib/python3.9/site-packages/pandas/io/formats/csvs.py", line 241, in save
    with get_handle(
  File "/home/alxavier/Documents/airflowalura/venv/lib/python3.9/site-packages/pandas/io/common.py", line 734, in get_handle
    check_parent_directory(str(handle))
  File "/home/alxavier/Documents/airflowalura/venv/lib/python3.9/site-packages/pandas/io/common.py", line 597, in check_parent_directory
    raise OSError(rf"Cannot save file into a non-existent directory: '{parent}'")
OSError: Cannot save file into a non-existent directory: '/home/alxavier/Documents/airflowalura/semana={data_interval_end}'
[2022-12-28 18:42:31,510] {taskinstance.py:1395} INFO - Marking task as FAILED. dag_id=dados_climaticos, task_id=extrai_dados, execution_date=20220912T000000, start_date=20221228T214229, end_date=20221228T214231
[2022-12-28 18:42:31,575] {standard_task_runner.py:92} ERROR - Failed to execute job 19 for task extrai_dados (Cannot save file into a non-existent directory: '/home/alxavier/Documents/airflowalura/semana={data_interval_end}'; 19917)
[2022-12-28 18:42:31,612] {local_task_job.py:156} INFO - Task exited with return code 1
[2022-12-28 18:42:31,702] {local_task_job.py:273} INFO - 0 downstream tasks scheduled from follow-on schedule check
[2022-12-28 18:44:46,545] {taskinstance.py:1159} INFO - Dependencies all met for <TaskInstance: dados_climaticos.extrai_dados scheduled__2022-09-12T00:00:00+00:00 [queued]>
[2022-12-28 18:44:46,560] {taskinstance.py:1159} INFO - Dependencies all met for <TaskInstance: dados_climaticos.extrai_dados scheduled__2022-09-12T00:00:00+00:00 [queued]>
[2022-12-28 18:44:46,560] {taskinstance.py:1356} INFO - 
--------------------------------------------------------------------------------
[2022-12-28 18:44:46,561] {taskinstance.py:1357} INFO - Starting attempt 1 of 1
[2022-12-28 18:44:46,561] {taskinstance.py:1358} INFO - 
--------------------------------------------------------------------------------
[2022-12-28 18:44:46,618] {taskinstance.py:1377} INFO - Executing <Task(PythonOperator): extrai_dados> on 2022-09-12 00:00:00+00:00
[2022-12-28 18:44:46,627] {standard_task_runner.py:52} INFO - Started process 20194 to run task
[2022-12-28 18:44:46,660] {standard_task_runner.py:79} INFO - Running: ['airflow', 'tasks', 'run', 'dados_climaticos', 'extrai_dados', 'scheduled__2022-09-12T00:00:00+00:00', '--job-id', '19', '--raw', '--subdir', 'DAGS_FOLDER/dados_climaticos.py', '--cfg-path', '/tmp/tmpns8xqkkz', '--error-file', '/tmp/tmp935714cm']
[2022-12-28 18:44:46,662] {standard_task_runner.py:80} INFO - Job 19: Subtask extrai_dados
[2022-12-28 18:44:46,865] {task_command.py:370} INFO - Running <TaskInstance: dados_climaticos.extrai_dados scheduled__2022-09-12T00:00:00+00:00 [running]> on host alxavier-airflow
[2022-12-28 18:44:47,030] {taskinstance.py:1569} INFO - Exporting the following env vars:
AIRFLOW_CTX_DAG_OWNER=airflow
AIRFLOW_CTX_DAG_ID=dados_climaticos
AIRFLOW_CTX_TASK_ID=extrai_dados
AIRFLOW_CTX_EXECUTION_DATE=2022-09-12T00:00:00+00:00
AIRFLOW_CTX_TRY_NUMBER=1
AIRFLOW_CTX_DAG_RUN_ID=scheduled__2022-09-12T00:00:00+00:00
[2022-12-28 18:44:47,928] {taskinstance.py:1889} ERROR - Task failed with exception
Traceback (most recent call last):
  File "/home/alxavier/Documents/airflowalura/venv/lib/python3.9/site-packages/airflow/operators/python.py", line 171, in execute
    return_value = self.execute_callable()
  File "/home/alxavier/Documents/airflowalura/venv/lib/python3.9/site-packages/airflow/operators/python.py", line 189, in execute_callable
    return self.python_callable(*self.op_args, **self.op_kwargs)
  File "/home/alxavier/Documents/airflowalura/dags/dados_climaticos.py", line 33, in extrai_dados
    dados.to_csv(file_path + 'dados_brutos.csv')
  File "/home/alxavier/Documents/airflowalura/venv/lib/python3.9/site-packages/pandas/util/_decorators.py", line 211, in wrapper
    return func(*args, **kwargs)
  File "/home/alxavier/Documents/airflowalura/venv/lib/python3.9/site-packages/pandas/core/generic.py", line 3720, in to_csv
    return DataFrameRenderer(formatter).to_csv(
  File "/home/alxavier/Documents/airflowalura/venv/lib/python3.9/site-packages/pandas/util/_decorators.py", line 211, in wrapper
    return func(*args, **kwargs)
  File "/home/alxavier/Documents/airflowalura/venv/lib/python3.9/site-packages/pandas/io/formats/format.py", line 1189, in to_csv
    csv_formatter.save()
  File "/home/alxavier/Documents/airflowalura/venv/lib/python3.9/site-packages/pandas/io/formats/csvs.py", line 241, in save
    with get_handle(
  File "/home/alxavier/Documents/airflowalura/venv/lib/python3.9/site-packages/pandas/io/common.py", line 734, in get_handle
    check_parent_directory(str(handle))
  File "/home/alxavier/Documents/airflowalura/venv/lib/python3.9/site-packages/pandas/io/common.py", line 597, in check_parent_directory
    raise OSError(rf"Cannot save file into a non-existent directory: '{parent}'")
OSError: Cannot save file into a non-existent directory: '/home/alxavier/Documents/airflowalura/semana={data_interval_end}'
[2022-12-28 18:44:47,950] {taskinstance.py:1395} INFO - Marking task as FAILED. dag_id=dados_climaticos, task_id=extrai_dados, execution_date=20220912T000000, start_date=20221228T214446, end_date=20221228T214447
[2022-12-28 18:44:47,998] {standard_task_runner.py:92} ERROR - Failed to execute job 19 for task extrai_dados (Cannot save file into a non-existent directory: '/home/alxavier/Documents/airflowalura/semana={data_interval_end}'; 20194)
[2022-12-28 18:44:48,023] {local_task_job.py:156} INFO - Task exited with return code 1
[2022-12-28 18:44:48,074] {local_task_job.py:273} INFO - 0 downstream tasks scheduled from follow-on schedule check
[2022-12-28 18:52:16,852] {taskinstance.py:1159} INFO - Dependencies all met for <TaskInstance: dados_climaticos.extrai_dados scheduled__2022-09-12T00:00:00+00:00 [queued]>
[2022-12-28 18:52:16,866] {taskinstance.py:1159} INFO - Dependencies all met for <TaskInstance: dados_climaticos.extrai_dados scheduled__2022-09-12T00:00:00+00:00 [queued]>
[2022-12-28 18:52:16,868] {taskinstance.py:1356} INFO - 
--------------------------------------------------------------------------------
[2022-12-28 18:52:16,868] {taskinstance.py:1357} INFO - Starting attempt 1 of 1
[2022-12-28 18:52:16,869] {taskinstance.py:1358} INFO - 
--------------------------------------------------------------------------------
[2022-12-28 18:52:16,912] {taskinstance.py:1377} INFO - Executing <Task(PythonOperator): extrai_dados> on 2022-09-12 00:00:00+00:00
[2022-12-28 18:52:16,920] {standard_task_runner.py:52} INFO - Started process 21009 to run task
[2022-12-28 18:52:16,927] {standard_task_runner.py:79} INFO - Running: ['airflow', 'tasks', 'run', 'dados_climaticos', 'extrai_dados', 'scheduled__2022-09-12T00:00:00+00:00', '--job-id', '19', '--raw', '--subdir', 'DAGS_FOLDER/dados_climaticos.py', '--cfg-path', '/tmp/tmp877dppdp', '--error-file', '/tmp/tmpkm44wulc']
[2022-12-28 18:52:16,939] {standard_task_runner.py:80} INFO - Job 19: Subtask extrai_dados
[2022-12-28 18:52:17,087] {task_command.py:370} INFO - Running <TaskInstance: dados_climaticos.extrai_dados scheduled__2022-09-12T00:00:00+00:00 [running]> on host alxavier-airflow
[2022-12-28 18:52:17,238] {taskinstance.py:1569} INFO - Exporting the following env vars:
AIRFLOW_CTX_DAG_OWNER=airflow
AIRFLOW_CTX_DAG_ID=dados_climaticos
AIRFLOW_CTX_TASK_ID=extrai_dados
AIRFLOW_CTX_EXECUTION_DATE=2022-09-12T00:00:00+00:00
AIRFLOW_CTX_TRY_NUMBER=1
AIRFLOW_CTX_DAG_RUN_ID=scheduled__2022-09-12T00:00:00+00:00
[2022-12-28 18:52:18,420] {python.py:173} INFO - Done. Returned value was: None
[2022-12-28 18:52:18,437] {taskinstance.py:1395} INFO - Marking task as SUCCESS. dag_id=dados_climaticos, task_id=extrai_dados, execution_date=20220912T000000, start_date=20221228T215216, end_date=20221228T215218
[2022-12-28 18:52:18,511] {local_task_job.py:156} INFO - Task exited with return code 0
[2022-12-28 18:52:18,547] {local_task_job.py:273} INFO - 0 downstream tasks scheduled from follow-on schedule check
