[2022-12-28 18:28:01,096] {taskinstance.py:1159} INFO - Dependencies all met for <TaskInstance: dados_climaticos.extrai_dados scheduled__2022-08-22T00:00:00+00:00 [queued]>
[2022-12-28 18:28:01,130] {taskinstance.py:1159} INFO - Dependencies all met for <TaskInstance: dados_climaticos.extrai_dados scheduled__2022-08-22T00:00:00+00:00 [queued]>
[2022-12-28 18:28:01,130] {taskinstance.py:1356} INFO - 
--------------------------------------------------------------------------------
[2022-12-28 18:28:01,135] {taskinstance.py:1357} INFO - Starting attempt 1 of 1
[2022-12-28 18:28:01,138] {taskinstance.py:1358} INFO - 
--------------------------------------------------------------------------------
[2022-12-28 18:28:01,256] {taskinstance.py:1377} INFO - Executing <Task(PythonOperator): extrai_dados> on 2022-08-22 00:00:00+00:00
[2022-12-28 18:28:01,274] {standard_task_runner.py:52} INFO - Started process 18373 to run task
[2022-12-28 18:28:01,319] {standard_task_runner.py:79} INFO - Running: ['airflow', 'tasks', 'run', 'dados_climaticos', 'extrai_dados', 'scheduled__2022-08-22T00:00:00+00:00', '--job-id', '13', '--raw', '--subdir', 'DAGS_FOLDER/dados_climaticos.py', '--cfg-path', '/tmp/tmpu5g1mann', '--error-file', '/tmp/tmpyfutecc9']
[2022-12-28 18:28:01,320] {standard_task_runner.py:80} INFO - Job 13: Subtask extrai_dados
[2022-12-28 18:28:01,753] {task_command.py:370} INFO - Running <TaskInstance: dados_climaticos.extrai_dados scheduled__2022-08-22T00:00:00+00:00 [running]> on host alxavier-airflow
[2022-12-28 18:28:01,873] {taskinstance.py:1889} ERROR - Task failed with exception
Traceback (most recent call last):
  File "/home/alxavier/Documents/airflowalura/venv/lib/python3.9/site-packages/airflow/models/taskinstance.py", line 1451, in _run_raw_task
    self._execute_task_with_callbacks(context, test_mode)
  File "/home/alxavier/Documents/airflowalura/venv/lib/python3.9/site-packages/airflow/models/taskinstance.py", line 1555, in _execute_task_with_callbacks
    task_orig = self.render_templates(context=context)
  File "/home/alxavier/Documents/airflowalura/venv/lib/python3.9/site-packages/airflow/models/taskinstance.py", line 2212, in render_templates
    rendered_task = self.task.render_template_fields(context)
  File "/home/alxavier/Documents/airflowalura/venv/lib/python3.9/site-packages/airflow/models/baseoperator.py", line 1185, in render_template_fields
    self._do_render_template_fields(self, self.template_fields, context, jinja_env, set())
  File "/home/alxavier/Documents/airflowalura/venv/lib/python3.9/site-packages/airflow/utils/session.py", line 71, in wrapper
    return func(*args, session=session, **kwargs)
  File "/home/alxavier/Documents/airflowalura/venv/lib/python3.9/site-packages/airflow/models/abstractoperator.py", line 344, in _do_render_template_fields
    rendered_content = self.render_template(
  File "/home/alxavier/Documents/airflowalura/venv/lib/python3.9/site-packages/airflow/models/abstractoperator.py", line 404, in render_template
    return {key: self.render_template(value, context, jinja_env) for key, value in value.items()}
  File "/home/alxavier/Documents/airflowalura/venv/lib/python3.9/site-packages/airflow/models/abstractoperator.py", line 404, in <dictcomp>
    return {key: self.render_template(value, context, jinja_env) for key, value in value.items()}
  File "/home/alxavier/Documents/airflowalura/venv/lib/python3.9/site-packages/airflow/models/abstractoperator.py", line 387, in render_template
    template = jinja_env.from_string(value)
  File "/home/alxavier/Documents/airflowalura/venv/lib/python3.9/site-packages/jinja2/environment.py", line 1092, in from_string
    return cls.from_code(self, self.compile(source), gs, None)
  File "/home/alxavier/Documents/airflowalura/venv/lib/python3.9/site-packages/jinja2/environment.py", line 757, in compile
    self.handle_exception(source=source_hint)
  File "/home/alxavier/Documents/airflowalura/venv/lib/python3.9/site-packages/jinja2/environment.py", line 925, in handle_exception
    raise rewrite_traceback_stack(source=source)
  File "<unknown>", line 1, in template
jinja2.exceptions.TemplateSyntaxError: unexpected char '"' at 29
[2022-12-28 18:28:01,894] {taskinstance.py:1395} INFO - Marking task as FAILED. dag_id=dados_climaticos, task_id=extrai_dados, execution_date=20220822T000000, start_date=20221228T212801, end_date=20221228T212801
[2022-12-28 18:28:02,000] {standard_task_runner.py:92} ERROR - Failed to execute job 13 for task extrai_dados (unexpected char '"' at 29; 18373)
[2022-12-28 18:28:02,043] {local_task_job.py:156} INFO - Task exited with return code 1
[2022-12-28 18:28:02,116] {local_task_job.py:273} INFO - 0 downstream tasks scheduled from follow-on schedule check
[2022-12-28 18:37:33,475] {taskinstance.py:1159} INFO - Dependencies all met for <TaskInstance: dados_climaticos.extrai_dados scheduled__2022-08-22T00:00:00+00:00 [queued]>
[2022-12-28 18:37:33,495] {taskinstance.py:1159} INFO - Dependencies all met for <TaskInstance: dados_climaticos.extrai_dados scheduled__2022-08-22T00:00:00+00:00 [queued]>
[2022-12-28 18:37:33,495] {taskinstance.py:1356} INFO - 
--------------------------------------------------------------------------------
[2022-12-28 18:37:33,496] {taskinstance.py:1357} INFO - Starting attempt 1 of 1
[2022-12-28 18:37:33,496] {taskinstance.py:1358} INFO - 
--------------------------------------------------------------------------------
[2022-12-28 18:37:33,542] {taskinstance.py:1377} INFO - Executing <Task(PythonOperator): extrai_dados> on 2022-08-22 00:00:00+00:00
[2022-12-28 18:37:33,547] {standard_task_runner.py:52} INFO - Started process 19409 to run task
[2022-12-28 18:37:33,558] {standard_task_runner.py:79} INFO - Running: ['airflow', 'tasks', 'run', 'dados_climaticos', 'extrai_dados', 'scheduled__2022-08-22T00:00:00+00:00', '--job-id', '13', '--raw', '--subdir', 'DAGS_FOLDER/dados_climaticos.py', '--cfg-path', '/tmp/tmpa4ttnt3w', '--error-file', '/tmp/tmpoqjm_24j']
[2022-12-28 18:37:33,559] {standard_task_runner.py:80} INFO - Job 13: Subtask extrai_dados
[2022-12-28 18:37:33,675] {task_command.py:370} INFO - Running <TaskInstance: dados_climaticos.extrai_dados scheduled__2022-08-22T00:00:00+00:00 [running]> on host alxavier-airflow
[2022-12-28 18:37:33,824] {taskinstance.py:1569} INFO - Exporting the following env vars:
AIRFLOW_CTX_DAG_OWNER=airflow
AIRFLOW_CTX_DAG_ID=dados_climaticos
AIRFLOW_CTX_TASK_ID=extrai_dados
AIRFLOW_CTX_EXECUTION_DATE=2022-08-22T00:00:00+00:00
AIRFLOW_CTX_TRY_NUMBER=1
AIRFLOW_CTX_DAG_RUN_ID=scheduled__2022-08-22T00:00:00+00:00
[2022-12-28 18:37:33,828] {taskinstance.py:1889} ERROR - Task failed with exception
Traceback (most recent call last):
  File "/home/alxavier/Documents/airflowalura/venv/lib/python3.9/site-packages/airflow/operators/python.py", line 171, in execute
    return_value = self.execute_callable()
  File "/home/alxavier/Documents/airflowalura/venv/lib/python3.9/site-packages/airflow/operators/python.py", line 189, in execute_callable
    return self.python_callable(*self.op_args, **self.op_kwargs)
  File "/home/alxavier/Documents/airflowalura/dags/dados_climaticos.py", line 27, in extrai_dados
    f'{city}/{data_interval_end}/{ds_add(data_interval_end, 7)}?unitGroup=metric&include=days&key={key}&contentType=csv')
  File "/home/alxavier/Documents/airflowalura/venv/lib/python3.9/site-packages/airflow/macros/__init__.py", line 44, in ds_add
    dt = datetime.strptime(str(ds), "%Y-%m-%d") + timedelta(days=days)
  File "/usr/lib/python3.9/_strptime.py", line 568, in _strptime_datetime
    tt, fraction, gmtoff_fraction = _strptime(data_string, format)
  File "/usr/lib/python3.9/_strptime.py", line 349, in _strptime
    raise ValueError("time data %r does not match format %r" %
ValueError: time data '2022-08_29' does not match format '%Y-%m-%d'
[2022-12-28 18:37:33,857] {taskinstance.py:1395} INFO - Marking task as FAILED. dag_id=dados_climaticos, task_id=extrai_dados, execution_date=20220822T000000, start_date=20221228T213733, end_date=20221228T213733
[2022-12-28 18:37:33,903] {standard_task_runner.py:92} ERROR - Failed to execute job 13 for task extrai_dados (time data '2022-08_29' does not match format '%Y-%m-%d'; 19409)
[2022-12-28 18:37:33,918] {local_task_job.py:156} INFO - Task exited with return code 1
[2022-12-28 18:37:33,990] {local_task_job.py:273} INFO - 0 downstream tasks scheduled from follow-on schedule check
[2022-12-28 18:41:53,458] {taskinstance.py:1159} INFO - Dependencies all met for <TaskInstance: dados_climaticos.extrai_dados scheduled__2022-08-22T00:00:00+00:00 [queued]>
[2022-12-28 18:41:53,496] {taskinstance.py:1159} INFO - Dependencies all met for <TaskInstance: dados_climaticos.extrai_dados scheduled__2022-08-22T00:00:00+00:00 [queued]>
[2022-12-28 18:41:53,497] {taskinstance.py:1356} INFO - 
--------------------------------------------------------------------------------
[2022-12-28 18:41:53,497] {taskinstance.py:1357} INFO - Starting attempt 1 of 1
[2022-12-28 18:41:53,497] {taskinstance.py:1358} INFO - 
--------------------------------------------------------------------------------
[2022-12-28 18:41:53,539] {taskinstance.py:1377} INFO - Executing <Task(PythonOperator): extrai_dados> on 2022-08-22 00:00:00+00:00
[2022-12-28 18:41:53,545] {standard_task_runner.py:52} INFO - Started process 19861 to run task
[2022-12-28 18:41:53,557] {standard_task_runner.py:79} INFO - Running: ['airflow', 'tasks', 'run', 'dados_climaticos', 'extrai_dados', 'scheduled__2022-08-22T00:00:00+00:00', '--job-id', '13', '--raw', '--subdir', 'DAGS_FOLDER/dados_climaticos.py', '--cfg-path', '/tmp/tmp8gdlzotn', '--error-file', '/tmp/tmpqei1xxnc']
[2022-12-28 18:41:53,558] {standard_task_runner.py:80} INFO - Job 13: Subtask extrai_dados
[2022-12-28 18:41:53,813] {task_command.py:370} INFO - Running <TaskInstance: dados_climaticos.extrai_dados scheduled__2022-08-22T00:00:00+00:00 [running]> on host alxavier-airflow
[2022-12-28 18:41:53,994] {taskinstance.py:1569} INFO - Exporting the following env vars:
AIRFLOW_CTX_DAG_OWNER=airflow
AIRFLOW_CTX_DAG_ID=dados_climaticos
AIRFLOW_CTX_TASK_ID=extrai_dados
AIRFLOW_CTX_EXECUTION_DATE=2022-08-22T00:00:00+00:00
AIRFLOW_CTX_TRY_NUMBER=1
AIRFLOW_CTX_DAG_RUN_ID=scheduled__2022-08-22T00:00:00+00:00
[2022-12-28 18:41:55,268] {taskinstance.py:1889} ERROR - Task failed with exception
Traceback (most recent call last):
  File "/home/alxavier/Documents/airflowalura/venv/lib/python3.9/site-packages/airflow/operators/python.py", line 171, in execute
    return_value = self.execute_callable()
  File "/home/alxavier/Documents/airflowalura/venv/lib/python3.9/site-packages/airflow/operators/python.py", line 189, in execute_callable
    return self.python_callable(*self.op_args, **self.op_kwargs)
  File "/home/alxavier/Documents/airflowalura/dags/dados_climaticos.py", line 33, in extrai_dados
    dados.to_csv(file_path + 'dados_brutos.csv')
  File "/home/alxavier/Documents/airflowalura/venv/lib/python3.9/site-packages/pandas/util/_decorators.py", line 211, in wrapper
    return func(*args, **kwargs)
  File "/home/alxavier/Documents/airflowalura/venv/lib/python3.9/site-packages/pandas/core/generic.py", line 3720, in to_csv
    return DataFrameRenderer(formatter).to_csv(
  File "/home/alxavier/Documents/airflowalura/venv/lib/python3.9/site-packages/pandas/util/_decorators.py", line 211, in wrapper
    return func(*args, **kwargs)
  File "/home/alxavier/Documents/airflowalura/venv/lib/python3.9/site-packages/pandas/io/formats/format.py", line 1189, in to_csv
    csv_formatter.save()
  File "/home/alxavier/Documents/airflowalura/venv/lib/python3.9/site-packages/pandas/io/formats/csvs.py", line 241, in save
    with get_handle(
  File "/home/alxavier/Documents/airflowalura/venv/lib/python3.9/site-packages/pandas/io/common.py", line 734, in get_handle
    check_parent_directory(str(handle))
  File "/home/alxavier/Documents/airflowalura/venv/lib/python3.9/site-packages/pandas/io/common.py", line 597, in check_parent_directory
    raise OSError(rf"Cannot save file into a non-existent directory: '{parent}'")
OSError: Cannot save file into a non-existent directory: '/home/alxavier/Documents/airflowalura/semana={data_interval_end}'
[2022-12-28 18:41:55,297] {taskinstance.py:1395} INFO - Marking task as FAILED. dag_id=dados_climaticos, task_id=extrai_dados, execution_date=20220822T000000, start_date=20221228T214153, end_date=20221228T214155
[2022-12-28 18:41:55,362] {standard_task_runner.py:92} ERROR - Failed to execute job 13 for task extrai_dados (Cannot save file into a non-existent directory: '/home/alxavier/Documents/airflowalura/semana={data_interval_end}'; 19861)
[2022-12-28 18:41:55,386] {local_task_job.py:156} INFO - Task exited with return code 1
[2022-12-28 18:41:55,447] {local_task_job.py:273} INFO - 0 downstream tasks scheduled from follow-on schedule check
[2022-12-28 18:43:59,410] {taskinstance.py:1159} INFO - Dependencies all met for <TaskInstance: dados_climaticos.extrai_dados scheduled__2022-08-22T00:00:00+00:00 [queued]>
[2022-12-28 18:43:59,424] {taskinstance.py:1159} INFO - Dependencies all met for <TaskInstance: dados_climaticos.extrai_dados scheduled__2022-08-22T00:00:00+00:00 [queued]>
[2022-12-28 18:43:59,424] {taskinstance.py:1356} INFO - 
--------------------------------------------------------------------------------
[2022-12-28 18:43:59,424] {taskinstance.py:1357} INFO - Starting attempt 1 of 1
[2022-12-28 18:43:59,424] {taskinstance.py:1358} INFO - 
--------------------------------------------------------------------------------
[2022-12-28 18:43:59,456] {taskinstance.py:1377} INFO - Executing <Task(PythonOperator): extrai_dados> on 2022-08-22 00:00:00+00:00
[2022-12-28 18:43:59,462] {standard_task_runner.py:52} INFO - Started process 20118 to run task
[2022-12-28 18:43:59,474] {standard_task_runner.py:79} INFO - Running: ['airflow', 'tasks', 'run', 'dados_climaticos', 'extrai_dados', 'scheduled__2022-08-22T00:00:00+00:00', '--job-id', '13', '--raw', '--subdir', 'DAGS_FOLDER/dados_climaticos.py', '--cfg-path', '/tmp/tmp0yd9x9yq', '--error-file', '/tmp/tmpskfuh4dh']
[2022-12-28 18:43:59,476] {standard_task_runner.py:80} INFO - Job 13: Subtask extrai_dados
[2022-12-28 18:43:59,612] {task_command.py:370} INFO - Running <TaskInstance: dados_climaticos.extrai_dados scheduled__2022-08-22T00:00:00+00:00 [running]> on host alxavier-airflow
[2022-12-28 18:43:59,788] {taskinstance.py:1569} INFO - Exporting the following env vars:
AIRFLOW_CTX_DAG_OWNER=airflow
AIRFLOW_CTX_DAG_ID=dados_climaticos
AIRFLOW_CTX_TASK_ID=extrai_dados
AIRFLOW_CTX_EXECUTION_DATE=2022-08-22T00:00:00+00:00
AIRFLOW_CTX_TRY_NUMBER=1
AIRFLOW_CTX_DAG_RUN_ID=scheduled__2022-08-22T00:00:00+00:00
[2022-12-28 18:44:00,942] {taskinstance.py:1889} ERROR - Task failed with exception
Traceback (most recent call last):
  File "/home/alxavier/Documents/airflowalura/venv/lib/python3.9/site-packages/airflow/operators/python.py", line 171, in execute
    return_value = self.execute_callable()
  File "/home/alxavier/Documents/airflowalura/venv/lib/python3.9/site-packages/airflow/operators/python.py", line 189, in execute_callable
    return self.python_callable(*self.op_args, **self.op_kwargs)
  File "/home/alxavier/Documents/airflowalura/dags/dados_climaticos.py", line 33, in extrai_dados
    dados.to_csv(file_path + 'dados_brutos.csv')
  File "/home/alxavier/Documents/airflowalura/venv/lib/python3.9/site-packages/pandas/util/_decorators.py", line 211, in wrapper
    return func(*args, **kwargs)
  File "/home/alxavier/Documents/airflowalura/venv/lib/python3.9/site-packages/pandas/core/generic.py", line 3720, in to_csv
    return DataFrameRenderer(formatter).to_csv(
  File "/home/alxavier/Documents/airflowalura/venv/lib/python3.9/site-packages/pandas/util/_decorators.py", line 211, in wrapper
    return func(*args, **kwargs)
  File "/home/alxavier/Documents/airflowalura/venv/lib/python3.9/site-packages/pandas/io/formats/format.py", line 1189, in to_csv
    csv_formatter.save()
  File "/home/alxavier/Documents/airflowalura/venv/lib/python3.9/site-packages/pandas/io/formats/csvs.py", line 241, in save
    with get_handle(
  File "/home/alxavier/Documents/airflowalura/venv/lib/python3.9/site-packages/pandas/io/common.py", line 734, in get_handle
    check_parent_directory(str(handle))
  File "/home/alxavier/Documents/airflowalura/venv/lib/python3.9/site-packages/pandas/io/common.py", line 597, in check_parent_directory
    raise OSError(rf"Cannot save file into a non-existent directory: '{parent}'")
OSError: Cannot save file into a non-existent directory: '/home/alxavier/Documents/airflowalura/semana={data_interval_end}'
[2022-12-28 18:44:00,983] {taskinstance.py:1395} INFO - Marking task as FAILED. dag_id=dados_climaticos, task_id=extrai_dados, execution_date=20220822T000000, start_date=20221228T214359, end_date=20221228T214400
[2022-12-28 18:44:01,097] {standard_task_runner.py:92} ERROR - Failed to execute job 13 for task extrai_dados (Cannot save file into a non-existent directory: '/home/alxavier/Documents/airflowalura/semana={data_interval_end}'; 20118)
[2022-12-28 18:44:01,139] {local_task_job.py:156} INFO - Task exited with return code 1
[2022-12-28 18:44:01,280] {local_task_job.py:273} INFO - 0 downstream tasks scheduled from follow-on schedule check
[2022-12-28 18:51:24,041] {taskinstance.py:1159} INFO - Dependencies all met for <TaskInstance: dados_climaticos.extrai_dados scheduled__2022-08-22T00:00:00+00:00 [queued]>
[2022-12-28 18:51:24,078] {taskinstance.py:1159} INFO - Dependencies all met for <TaskInstance: dados_climaticos.extrai_dados scheduled__2022-08-22T00:00:00+00:00 [queued]>
[2022-12-28 18:51:24,079] {taskinstance.py:1356} INFO - 
--------------------------------------------------------------------------------
[2022-12-28 18:51:24,079] {taskinstance.py:1357} INFO - Starting attempt 1 of 1
[2022-12-28 18:51:24,079] {taskinstance.py:1358} INFO - 
--------------------------------------------------------------------------------
[2022-12-28 18:51:24,146] {taskinstance.py:1377} INFO - Executing <Task(PythonOperator): extrai_dados> on 2022-08-22 00:00:00+00:00
[2022-12-28 18:51:24,158] {standard_task_runner.py:52} INFO - Started process 20932 to run task
[2022-12-28 18:51:24,182] {standard_task_runner.py:79} INFO - Running: ['airflow', 'tasks', 'run', 'dados_climaticos', 'extrai_dados', 'scheduled__2022-08-22T00:00:00+00:00', '--job-id', '13', '--raw', '--subdir', 'DAGS_FOLDER/dados_climaticos.py', '--cfg-path', '/tmp/tmpsqgegaan', '--error-file', '/tmp/tmpxp7hvvhd']
[2022-12-28 18:51:24,187] {standard_task_runner.py:80} INFO - Job 13: Subtask extrai_dados
[2022-12-28 18:51:24,484] {task_command.py:370} INFO - Running <TaskInstance: dados_climaticos.extrai_dados scheduled__2022-08-22T00:00:00+00:00 [running]> on host alxavier-airflow
[2022-12-28 18:51:24,960] {taskinstance.py:1569} INFO - Exporting the following env vars:
AIRFLOW_CTX_DAG_OWNER=airflow
AIRFLOW_CTX_DAG_ID=dados_climaticos
AIRFLOW_CTX_TASK_ID=extrai_dados
AIRFLOW_CTX_EXECUTION_DATE=2022-08-22T00:00:00+00:00
AIRFLOW_CTX_TRY_NUMBER=1
AIRFLOW_CTX_DAG_RUN_ID=scheduled__2022-08-22T00:00:00+00:00
[2022-12-28 18:51:31,210] {python.py:173} INFO - Done. Returned value was: None
[2022-12-28 18:51:31,249] {taskinstance.py:1395} INFO - Marking task as SUCCESS. dag_id=dados_climaticos, task_id=extrai_dados, execution_date=20220822T000000, start_date=20221228T215124, end_date=20221228T215131
[2022-12-28 18:51:31,447] {local_task_job.py:156} INFO - Task exited with return code 0
[2022-12-28 18:51:31,551] {local_task_job.py:273} INFO - 0 downstream tasks scheduled from follow-on schedule check
